<?xml version="1.0"?>
<robot  name="Robot">
 <link  name="L3" >
  <visual >
   <origin  xyz="-2.0816681711721685e-17 0.0 0.4330127018922193"  rpy="0.0 0.0 0.0" />
   <geometry >
    <box  size="0.03999999910593033 0.03999999910593033 0.24867513548888254" />
   </geometry>
   <material  name="L3_Material" >
    <color  rgba="0.44074609925444386 0.5905354521064672 0.08480606961981618 1.0" />
   </material>
  </visual>
  <collision  name="L3_0_Collision" >
   <origin  xyz="-2.0816681711721685e-17 0.0 0.4330127018922193"  rpy="0.0 0.0 0.0" />
   <geometry >
    <box  size="0.03999999910593033 0.03999999910593033 0.24867513548888254" />
   </geometry>
  </collision>
  <visual >
   <origin  xyz="-6.938893903907228e-18 0.0 0.14433756729740643"  rpy="0.0 0.0 0.0" />
   <geometry >
    <box  size="0.03999999910593033 0.03999999910593033 0.24867513548888254" />
   </geometry>
   <material  name="L3_Material" >
    <color  rgba="0.44074609925444386 0.5905354521064672 0.08480606961981618 1.0" />
   </material>
  </visual>
  <collision  name="L3_1_Collision" >
   <origin  xyz="-6.938893903907228e-18 0.0 0.14433756729740643"  rpy="0.0 0.0 0.0" />
   <geometry >
    <box  size="0.03999999910593033 0.03999999910593033 0.24867513548888254" />
   </geometry>
  </collision>
  <visual >
   <origin  xyz="-1.3877787807814457e-17 0.0 0.28867513459481287"  rpy="0.0 0.0 0.0" />
   <geometry >
    <box  size="0.03999999910593033 0.03999999910593033 0.5373502700836954" />
   </geometry>
   <material  name="L3_Material" >
    <color  rgba="0.44074609925444386 0.5905354521064672 0.08480606961981618 1.0" />
   </material>
  </visual>
  <collision  name="L3_2_Collision" >
   <origin  xyz="-1.3877787807814457e-17 0.0 0.28867513459481287"  rpy="0.0 0.0 0.0" />
   <geometry >
    <box  size="0.03999999910593033 0.03999999910593033 0.5373502700836954" />
   </geometry>
  </collision>
  <inertial >
   <origin  xyz="-0.0 0.0 0.28868"  rpy="0.0 0.0 0.0" />
   <mass  value="0.8907689643113298" />
   <inertia  ixz="0.07992171105215214"  iyz="0.0"  iyy="0.3018999396288964"  izz="0.024951427653936358"  ixy="1.089042360755529e-19"  ixx="0.2771860503548242" />
  </inertial>
 </link>
 <link  name="G" >
  <visual >
   <origin  xyz="0.0 0.0 0.0"  rpy="0.0 0.0 0.0" />
   <geometry >
    <box  size="0.08 0.08 0.08" />
   </geometry>
   <material  name="G_Material" >
    <color  rgba="0.4455553401076836 0.021199425119947546 0.9921228570683995 1.0" />
   </material>
  </visual>
  <collision  name="G_Collision" >
   <origin  xyz="0.0 0.0 0.0"  rpy="0.0 0.0 0.0" />
   <geometry >
    <box  size="0.08 0.08 0.08" />
   </geometry>
  </collision>
  <inertial >
   <origin  xyz="0.0 0.0 0.0"  rpy="0.0 0.0 0.0" />
   <mass  value="0.4937142857142858" />
   <inertia  ixz="0.0"  iyz="0.0"  iyy="0.0005266285714285715"  izz="0.0005266285714285715"  ixy="0.0"  ixx="0.0005266285714285715" />
  </inertial>
 </link>
 <link  name="L4" >
  <visual >
   <origin  xyz="2.7755575615628914e-17 0.0 0.28867513459481287"  rpy="0.0 0.0 0.0" />
   <geometry >
    <box  size="0.03999999910593033 0.03999999910593033 0.5373502700836954" />
   </geometry>
   <material  name="L4_Material" >
    <color  rgba="0.8559306353982249 0.7466780247296667 0.04568936286583325 1.0" />
   </material>
  </visual>
  <collision  name="L4_0_Collision" >
   <origin  xyz="2.7755575615628914e-17 0.0 0.28867513459481287"  rpy="0.0 0.0 0.0" />
   <geometry >
    <box  size="0.03999999910593033 0.03999999910593033 0.5373502700836954" />
   </geometry>
  </collision>
  <visual >
   <origin  xyz="2.7755575615628914e-17 0.0 0.14433756729740643"  rpy="0.0 0.0 0.0" />
   <geometry >
    <box  size="0.03999999910593033 0.03999999910593033 0.24867513548888254" />
   </geometry>
   <material  name="L4_Material" >
    <color  rgba="0.8559306353982249 0.7466780247296667 0.04568936286583325 1.0" />
   </material>
  </visual>
  <collision  name="L4_1_Collision" >
   <origin  xyz="2.7755575615628914e-17 0.0 0.14433756729740643"  rpy="0.0 0.0 0.0" />
   <geometry >
    <box  size="0.03999999910593033 0.03999999910593033 0.24867513548888254" />
   </geometry>
  </collision>
  <visual >
   <origin  xyz="5.551115123125783e-17 0.0 0.4330127018922193"  rpy="0.0 0.0 0.0" />
   <geometry >
    <box  size="0.03999999910593033 0.03999999910593033 0.24867513548888254" />
   </geometry>
   <material  name="L4_Material" >
    <color  rgba="0.8559306353982249 0.7466780247296667 0.04568936286583325 1.0" />
   </material>
  </visual>
  <collision  name="L4_2_Collision" >
   <origin  xyz="5.551115123125783e-17 0.0 0.4330127018922193"  rpy="0.0 0.0 0.0" />
   <geometry >
    <box  size="0.03999999910593033 0.03999999910593033 0.24867513548888254" />
   </geometry>
  </collision>
  <inertial >
   <origin  xyz="0.0 0.0 0.28868"  rpy="0.0 0.0 0.0" />
   <mass  value="0.890768782780219" />
   <inertia  ixz="0.12288168914925403"  iyz="1.9457989558330127e-11"  iyy="1.004431387018112"  izz="0.024951424576292305"  ixy="1.1234074518331488e-11"  ixx="0.9797175007691247" />
  </inertial>
 </link>
 <link  name="EE" >
  <visual >
   <origin  xyz="0.0 0.0 0.0"  rpy="0.0 0.0 0.0" />
   <geometry >
    <sphere  radius="0.028571428571428574" />
   </geometry>
   <material  name="EE_Material" >
    <color  rgba="0.18745021040874899 0.3921332715770274 0.20689540261187223 1.0" />
   </material>
  </visual>
  <collision  name="EE_Collision" >
   <origin  xyz="0.0 0.0 0.0"  rpy="0.0 0.0 0.0" />
   <geometry >
    <sphere  radius="0.028571428571428574" />
   </geometry>
  </collision>
  <inertial >
   <origin  xyz="0.0 0.0 0.0"  rpy="0.0 0.0 0.0" />
   <mass  value="0.09420852605517083" />
   <inertia  ixz="0.0"  iyz="0.0"  iyy="3.0761967691484357e-05"  izz="3.0761967691484357e-05"  ixy="0.0"  ixx="3.0761967691484357e-05" />
  </inertial>
 </link>
 <link  name="L8" >
  <visual >
   <origin  xyz="0.0 0.0 0.09567"  rpy="0.0 0.0 0.0" />
   <geometry >
    <box  size="0.04 0.04 0.15134171618254486" />
   </geometry>
   <material  name="L8_Material" >
    <color  rgba="0.9489117330034907 0.9284521836428632 0.18824955644449526 1.0" />
   </material>
  </visual>
  <collision  name="L8_Collision" >
   <origin  xyz="0.0 0.0 0.09567"  rpy="0.0 0.0 0.0" />
   <geometry >
    <box  size="0.04 0.04 0.15134171618254486" />
   </geometry>
  </collision>
  <inertial >
   <origin  xyz="0.0 0.0 0.09567"  rpy="0.0 0.0 0.0" />
   <mass  value="0.2334986478244978" />
   <inertia  ixz="0.0"  iyz="0.0"  iyy="0.0004768103693077654"  izz="6.226630608653275e-05"  ixy="0.0"  ixx="0.0004768103693077654" />
  </inertial>
 </link>
 <link  name="L7" >
  <visual >
   <origin  xyz="-0.08348220290987414 0.0 0.27166586136223553"  rpy="0.0 -0.2981381045556848 0.0" />
   <geometry >
    <box  size="0.03999999910593033 0.03999999910593033 0.5284069622602048" />
   </geometry>
   <material  name="L7_Material" >
    <color  rgba="0.743225161276551 0.7365706971572281 0.8635250496308112 1.0" />
   </material>
  </visual>
  <collision  name="L7_0_Collision" >
   <origin  xyz="-0.08348220290987414 0.0 0.27166586136223553"  rpy="0.0 -0.2981381045556848 0.0" />
   <geometry >
    <box  size="0.03999999910593033 0.03999999910593033 0.5284069622602048" />
   </geometry>
  </collision>
  <visual >
   <origin  xyz="-1.1102230246251565e-16 0.0 0.31839524061378355"  rpy="0.0 0.0 0.0" />
   <geometry >
    <box  size="0.03999999910593033 0.03999999910593033 0.5967904821216368" />
   </geometry>
   <material  name="L7_Material" >
    <color  rgba="0.743225161276551 0.7365706971572281 0.8635250496308112 1.0" />
   </material>
  </visual>
  <collision  name="L7_1_Collision" >
   <origin  xyz="-1.1102230246251565e-16 0.0 0.31839524061378355"  rpy="0.0 0.0 0.0" />
   <geometry >
    <box  size="0.03999999910593033 0.03999999910593033 0.5967904821216368" />
   </geometry>
  </collision>
  <visual >
   <origin  xyz="-0.08348220290987425 0.0 0.5900611019760191"  rpy="0.0 1.0604963701704433 0.0" />
   <geometry >
    <box  size="0.03999999910593033 0.03999999910593033 0.15134171707661453" />
   </geometry>
   <material  name="L7_Material" >
    <color  rgba="0.743225161276551 0.7365706971572281 0.8635250496308112 1.0" />
   </material>
  </visual>
  <collision  name="L7_2_Collision" >
   <origin  xyz="-0.08348220290987425 0.0 0.5900611019760191"  rpy="0.0 1.0604963701704433 0.0" />
   <geometry >
    <box  size="0.03999999910593033 0.03999999910593033 0.15134171707661453" />
   </geometry>
  </collision>
  <inertial >
   <origin  xyz="-0.05565 0.0 0.39337"  rpy="0.0 0.0 0.0" />
   <mass  value="2.013151705710374" />
   <inertia  ixz="-0.2161467496764618"  iyz="-2.1419829672520126e-19"  iyy="0.9622692836418173"  izz="0.11074845174673736"  ixy="9.015364922924458e-19"  ixx="0.8520576723259374" />
  </inertial>
 </link>
 <link  name="L6" >
  <visual >
   <origin  xyz="0.0 0.0 0.09567"  rpy="0.0 0.0 0.0" />
   <geometry >
    <box  size="0.04 0.04 0.15134171618254486" />
   </geometry>
   <material  name="L6_Material" >
    <color  rgba="0.4522280606632063 0.7847087756890495 0.6589466429160912 1.0" />
   </material>
  </visual>
  <collision  name="L6_Collision" >
   <origin  xyz="0.0 0.0 0.09567"  rpy="0.0 0.0 0.0" />
   <geometry >
    <box  size="0.04 0.04 0.15134171618254486" />
   </geometry>
  </collision>
  <inertial >
   <origin  xyz="0.0 0.0 0.09567"  rpy="0.0 0.0 0.0" />
   <mass  value="0.2334986478244978" />
   <inertia  ixz="0.0"  iyz="0.0"  iyy="0.0004768103693077654"  izz="6.226630608653275e-05"  ixy="0.0"  ixx="0.0004768103693077654" />
  </inertial>
 </link>
 <link  name="L5" >
  <visual >
   <origin  xyz="0.0 0.0 0.09567"  rpy="0.0 0.0 0.0" />
   <geometry >
    <box  size="0.04 0.04 0.1513417161825449" />
   </geometry>
   <material  name="L5_Material" >
    <color  rgba="0.3072069057733231 0.954402801538666 0.12209650394690086 1.0" />
   </material>
  </visual>
  <collision  name="L5_Collision" >
   <origin  xyz="0.0 0.0 0.09567"  rpy="0.0 0.0 0.0" />
   <geometry >
    <box  size="0.04 0.04 0.1513417161825449" />
   </geometry>
  </collision>
  <inertial >
   <origin  xyz="0.0 0.0 0.09567"  rpy="0.0 0.0 0.0" />
   <mass  value="0.2334986478244979" />
   <inertia  ixz="0.0"  iyz="0.0"  iyy="0.0004768103693077659"  izz="6.226630608653276e-05"  ixy="0.0"  ixx="0.0004768103693077659" />
  </inertial>
 </link>
 <joint  type="revolute"  name="TL_ground" >
  <parent  link="G" />
  <child  link="L3" />
  <origin  xyz="0.0 0.0 0.0"  rpy="3.141592653589793 0.5235987755982991 3.141592653589793" />
  <axis  xyz="0 1 0" />
  <limit  lower="-3.141592653589793"  effort="10.799999999999999"  velocity="29.845130209103036"  upper="3.141592653589793" />
  <dynamics  damping="0.05"  friction="0" />
 </joint>
 <joint  type="fixed"  name="TL_ground_G_WeldActuator" >
  <parent  link="G" />
  <child  link="TL_ground_GActuator" />
  <origin  xyz="0.0 0.05925 0.0"  rpy="-1.5707963267948966 0.5235987755982991 -3.141592653589793" />
 </joint>
 <link  name="TL_ground_GActuator" >
  <visual >
   <geometry >
    <cylinder  length="0.0385"  radius="0.0425" />
   </geometry>
   <material  name="TL_ground_GActuator_Material" >
    <color  rgba="0.4455553401076836 0.021199425119947546 0.9921228570683995 0.9" />
   </material>
  </visual>
  <inertial >
   <inertia  ixz="0.0"  iyz="0.0"  iyy="0.006709166666666667"  izz="0.010306250000000001"  ixy="0.0"  ixx="0.006709166666666667" />
   <mass  value="0.1" />
  </inertial>
 </link>
 <link  name="TL_ground_GUnit" >
  <visual >
   <geometry >
    <cylinder  length="0.08"  radius="0.04" />
   </geometry>
   <material  name="TL_ground_GUnit_Material" >
    <color  rgba="0.4455553401076836 0.021199425119947546 0.9921228570683995 0.9" />
   </material>
  </visual>
  <inertial >
   <inertia  ixz="0.0"  iyz="0.0"  iyy="0.0016666666666666666"  izz="0.002"  ixy="0.0"  ixx="0.0016666666666666666" />
   <mass  value="0.1" />
  </inertial>
 </link>
 <joint  type="fixed"  name="TL_ground_G_WeldUnit" >
  <parent  link="G" />
  <child  link="TL_ground_GUnit" />
  <origin  xyz="0.0 0.0 0.0"  rpy="-1.5707963267948966 0.5235987755982991 -3.141592653589793" />
 </joint>
 <joint  type="revolute"  name="TL_knee" >
  <parent  link="L3" />
  <child  link="L4" />
  <origin  xyz="-2.7755575615628914e-17 0.0 0.5773502691896257"  rpy="0.0 1.0471975511965979 0.0" />
  <axis  xyz="0 1 0" />
  <limit  lower="-3.141592653589793"  effort="600.0"  velocity="6.283185307179586"  upper="3.141592653589793" />
  <dynamics  damping="0.05"  friction="0" />
 </joint>
 <link  name="TL_knee_L3Unit" >
  <visual >
   <geometry >
    <cylinder  length="0.03999999910593033"  radius="0.019999999552965164" />
   </geometry>
   <material  name="TL_knee_L3Unit_Material" >
    <color  rgba="0.44074609925444386 0.5905354521064672 0.08480606961981618 0.9" />
   </material>
  </visual>
  <inertial >
   <inertia  ixz="0.0"  iyz="0.0"  iyy="0.0008333333147068819"  izz="0.0009999999776482583"  ixy="0.0"  ixx="0.0008333333147068819" />
   <mass  value="0.1" />
  </inertial>
 </link>
 <joint  type="fixed"  name="TL_knee_L3_WeldUnit" >
  <parent  link="L3" />
  <child  link="TL_knee_L3Unit" />
  <origin  xyz="-2.7755575615628914e-17 0.0 0.5773502691896257"  rpy="1.5707963267948961 1.0471975511965979 -2.220446049250313e-16" />
 </joint>
 <joint  type="revolute"  name="TL_ee" >
  <parent  link="L4" />
  <child  link="EE" />
  <origin  xyz="5.551115123125783e-17 0.0 0.5773502691896257"  rpy="3.141592653589793 0.5235987755982991 3.141592653589793" />
  <axis  xyz="0 1 0" />
  <limit  lower="-3.141592653589793"  effort="600.0"  velocity="6.283185307179586"  upper="3.141592653589793" />
  <dynamics  damping="0.05"  friction="0" />
 </joint>
 <link  name="TL_ee_L4Unit" >
  <visual >
   <geometry >
    <cylinder  length="0.03999999910593033"  radius="0.019999999552965164" />
   </geometry>
   <material  name="TL_ee_L4Unit_Material" >
    <color  rgba="0.8559306353982249 0.7466780247296667 0.04568936286583325 0.9" />
   </material>
  </visual>
  <inertial >
   <inertia  ixz="0.0"  iyz="0.0"  iyy="0.0008333333147068819"  izz="0.0009999999776482583"  ixy="0.0"  ixx="0.0008333333147068819" />
   <mass  value="0.1" />
  </inertial>
 </link>
 <joint  type="fixed"  name="TL_ee_L4_WeldUnit" >
  <parent  link="L4" />
  <child  link="TL_ee_L4Unit" />
  <origin  xyz="5.551115123125783e-17 0.0 0.5773502691896257"  rpy="-1.5707963267948966 0.5235987755982991 -3.141592653589793" />
 </joint>
 <link  name="FL_branch_top_L8Pseudo" >
  <visual >
   <geometry >
    <sphere  radius="0.028571428571428574" />
   </geometry>
   <material  name="FL_branch_top_L8Pseudo_Material" >
    <color  rgba="0.9489117330034907 0.9284521836428632 0.18824955644449526 0.5" />
   </material>
  </visual>
  <inertial >
   <mass  value="0.05" />
   <inertia  ixz="0.0"  iyz="0.0"  iyy="1.6326530612244903e-05"  izz="1.6326530612244903e-05"  ixy="0.0"  ixx="1.6326530612244903e-05" />
  </inertial>
 </link>
 <joint  type="revolute"  name="FL_branch_top_L8_revolute" >
  <parent  link="L8" />
  <child  link="FL_branch_top_L8Pseudo" />
  <origin  xyz="0.0 0.0 0.19134171618254486"  rpy="0.0 0.0 0.0" />
  <axis  xyz="0 1 0" />
  <limit  lower="-3.141592653589793"  effort="600.0"  velocity="6.283185307179586"  upper="3.141592653589793" />
  <dynamics  damping="0.05"  friction="0" />
 </joint>
 <joint  type="fixed"  name="FL_branch_top_L8_Weld" >
  <parent  link="L3" />
  <child  link="FL_branch_top_L3Pseudo" />
  <origin  xyz="2.7755575615628914e-17 0.0 0.28867513459481287"  rpy="0.0 -1.439896632895322 0.0" />
 </joint>
 <link  name="FL_branch_top_L3Pseudo" >
  <visual >
   <geometry >
    <sphere  radius="0.02857142793280738" />
   </geometry>
   <material  name="FL_branch_top_L3Pseudo_Material" >
    <color  rgba="0.44074609925444386 0.5905354521064672 0.08480606961981618 0.5" />
   </material>
  </visual>
  <inertial >
   <mass  value="0.05" />
   <inertia  ixz="0.0"  iyz="0.0"  iyy="1.632652988239212e-05"  izz="1.632652988239212e-05"  ixy="0.0"  ixx="1.632652988239212e-05" />
  </inertial>
 </link>
 <joint  type="revolute"  name="FL_branch_j0" >
  <parent  link="L7" />
  <child  link="L8" />
  <origin  xyz="-0.16696440581974828 0.0 0.5433317227244711"  rpy="0.0 -1.295698120021902 0.0" />
  <axis  xyz="0 1 0" />
  <limit  lower="-3.141592653589793"  effort="600.0"  velocity="6.283185307179586"  upper="3.141592653589793" />
  <dynamics  damping="0.05"  friction="0" />
 </joint>
 <link  name="FL_branch_j0_L7Unit" >
  <visual >
   <geometry >
    <cylinder  length="0.03999999910593033"  radius="0.019999999552965164" />
   </geometry>
   <material  name="FL_branch_j0_L7Unit_Material" >
    <color  rgba="0.743225161276551 0.7365706971572281 0.8635250496308112 0.9" />
   </material>
  </visual>
  <inertial >
   <inertia  ixz="0.0"  iyz="0.0"  iyy="0.0008333333147068819"  izz="0.0009999999776482583"  ixy="0.0"  ixx="0.0008333333147068819" />
   <mass  value="0.1" />
  </inertial>
 </link>
 <joint  type="fixed"  name="FL_branch_j0_L7_WeldUnit" >
  <parent  link="L7" />
  <child  link="FL_branch_j0_L7Unit" />
  <origin  xyz="-0.16696440581974828 0.0 0.5433317227244711"  rpy="1.5707963267948961 -1.295698120021902 2.220446049250313e-16" />
 </joint>
 <joint  type="revolute"  name="FL_branch_j1" >
  <parent  link="L7" />
  <child  link="L6" />
  <origin  xyz="-2.220446049250313e-16 0.0 0.6367904812275671"  rpy="0.0 0.27509820677299457 0.0" />
  <axis  xyz="0 1 0" />
  <limit  lower="-3.141592653589793"  effort="600.0"  velocity="6.283185307179586"  upper="3.141592653589793" />
  <dynamics  damping="0.05"  friction="0" />
 </joint>
 <link  name="FL_branch_j1_L7Unit" >
  <visual >
   <geometry >
    <cylinder  length="0.03999999910593033"  radius="0.019999999552965164" />
   </geometry>
   <material  name="FL_branch_j1_L7Unit_Material" >
    <color  rgba="0.743225161276551 0.7365706971572281 0.8635250496308112 0.9" />
   </material>
  </visual>
  <inertial >
   <inertia  ixz="0.0"  iyz="0.0"  iyy="0.0008333333147068819"  izz="0.0009999999776482583"  ixy="0.0"  ixx="0.0008333333147068819" />
   <mass  value="0.1" />
  </inertial>
 </link>
 <joint  type="fixed"  name="FL_branch_j1_L7_WeldUnit" >
  <parent  link="L7" />
  <child  link="FL_branch_j1_L7Unit" />
  <origin  xyz="-2.220446049250313e-16 0.0 0.6367904812275671"  rpy="1.5707963267948966 0.27509820677299457 1.1102230246251565e-16" />
 </joint>
 <joint  type="revolute"  name="FL_branch_j2" >
  <parent  link="L6" />
  <child  link="L5" />
  <origin  xyz="0.0 0.0 0.19134171618254486"  rpy="0.0 -0.7853981633974484 0.0" />
  <axis  xyz="0 1 0" />
  <limit  lower="-3.141592653589793"  effort="600.0"  velocity="6.283185307179586"  upper="3.141592653589793" />
  <dynamics  damping="0.05"  friction="0" />
 </joint>
 <link  name="FL_branch_j2_L6Unit" >
  <visual >
   <geometry >
    <cylinder  length="0.04"  radius="0.02" />
   </geometry>
   <material  name="FL_branch_j2_L6Unit_Material" >
    <color  rgba="0.4522280606632063 0.7847087756890495 0.6589466429160912 0.9" />
   </material>
  </visual>
  <inertial >
   <inertia  ixz="0.0"  iyz="0.0"  iyy="0.0008333333333333333"  izz="0.001"  ixy="0.0"  ixx="0.0008333333333333333" />
   <mass  value="0.1" />
  </inertial>
 </link>
 <joint  type="fixed"  name="FL_branch_j2_L6_WeldUnit" >
  <parent  link="L6" />
  <child  link="FL_branch_j2_L6Unit" />
  <origin  xyz="0.0 0.0 0.19134171618254486"  rpy="1.5707963267948961 -0.7853981633974483 1.1102230246251565e-16" />
 </joint>
 <link  name="FL_branch_bot_L5Pseudo" >
  <visual >
   <geometry >
    <sphere  radius="0.028571428571428574" />
   </geometry>
   <material  name="FL_branch_bot_L5Pseudo_Material" >
    <color  rgba="0.3072069057733231 0.954402801538666 0.12209650394690086 0.5" />
   </material>
  </visual>
  <inertial >
   <mass  value="0.05" />
   <inertia  ixz="0.0"  iyz="0.0"  iyy="1.6326530612244903e-05"  izz="1.6326530612244903e-05"  ixy="0.0"  ixx="1.6326530612244903e-05" />
  </inertial>
 </link>
 <joint  type="revolute"  name="FL_branch_bot_L5_revolute" >
  <parent  link="L5" />
  <child  link="FL_branch_bot_L5Pseudo" />
  <origin  xyz="0.0 0.0 0.1913417161825449"  rpy="0.0 0.0 0.0" />
  <axis  xyz="0 1 0" />
  <limit  lower="-3.141592653589793"  effort="600.0"  velocity="6.283185307179586"  upper="3.141592653589793" />
  <dynamics  damping="0.05"  friction="0" />
 </joint>
 <joint  type="fixed"  name="FL_branch_bot_L5_Weld" >
  <parent  link="L4" />
  <child  link="FL_branch_bot_L4Pseudo" />
  <origin  xyz="2.7755575615628914e-17 0.0 0.2886751345948128"  rpy="3.141592653589793 -1.439896632895322 3.141592653589793" />
 </joint>
 <link  name="FL_branch_bot_L4Pseudo" >
  <visual >
   <geometry >
    <sphere  radius="0.02857142793280738" />
   </geometry>
   <material  name="FL_branch_bot_L4Pseudo_Material" >
    <color  rgba="0.8559306353982249 0.7466780247296667 0.04568936286583325 0.5" />
   </material>
  </visual>
  <inertial >
   <mass  value="0.05" />
   <inertia  ixz="0.0"  iyz="0.0"  iyy="1.632652988239212e-05"  izz="1.632652988239212e-05"  ixy="0.0"  ixx="1.632652988239212e-05" />
  </inertial>
 </link>
 <joint  type="revolute"  name="FL_branch_ground" >
  <parent  link="G" />
  <child  link="L7" />
  <origin  xyz="-0.5 0.0 0.0"  rpy="3.141592653589793 0.6677972884717187 3.141592653589793" />
  <axis  xyz="0 1 0" />
  <limit  lower="-3.141592653589793"  effort="10.799999999999999"  velocity="29.845130209103036"  upper="3.141592653589793" />
  <dynamics  damping="0.05"  friction="0" />
 </joint>
 <joint  type="fixed"  name="FL_branch_ground_G_WeldActuator" >
  <parent  link="G" />
  <child  link="FL_branch_ground_GActuator" />
  <origin  xyz="-0.5 0.05925 0.0"  rpy="-1.5707963267948966 0.6677972884717187 -3.141592653589793" />
 </joint>
 <link  name="FL_branch_ground_GActuator" >
  <visual >
   <geometry >
    <cylinder  length="0.0385"  radius="0.0425" />
   </geometry>
   <material  name="FL_branch_ground_GActuator_Material" >
    <color  rgba="0.4455553401076836 0.021199425119947546 0.9921228570683995 0.9" />
   </material>
  </visual>
  <inertial >
   <inertia  ixz="0.0"  iyz="0.0"  iyy="0.006709166666666667"  izz="0.010306250000000001"  ixy="0.0"  ixx="0.006709166666666667" />
   <mass  value="0.1" />
  </inertial>
 </link>
 <link  name="FL_branch_ground_GUnit" >
  <visual >
   <geometry >
    <cylinder  length="0.08"  radius="0.04" />
   </geometry>
   <material  name="FL_branch_ground_GUnit_Material" >
    <color  rgba="0.4455553401076836 0.021199425119947546 0.9921228570683995 0.9" />
   </material>
  </visual>
  <inertial >
   <inertia  ixz="0.0"  iyz="0.0"  iyy="0.0016666666666666666"  izz="0.002"  ixy="0.0"  ixx="0.0016666666666666666" />
   <mass  value="0.1" />
  </inertial>
 </link>
 <joint  type="fixed"  name="FL_branch_ground_G_WeldUnit" >
  <parent  link="G" />
  <child  link="FL_branch_ground_GUnit" />
  <origin  xyz="-0.5 0.0 0.0"  rpy="-1.5707963267948966 0.6677972884717187 -3.141592653589793" />
 </joint>
 </robot>