<?xml version="1.0"?>
<robot  name="Robot" >
 <link  name="G" >
  <visual >
   <origin  rpy="0.0 0.0 0.0"  xyz="0.0 0.0 0.0" />
   <geometry >
    <box  size="0.08 0.08 0.08" />
   </geometry>
   <material  name="G_Material" >
    <color  rgba="0.20856352241202425 0.6597387408684208 0.8100469130840032 1.0" />
   </material>
  </visual>
  <collision  name="G_Collision" >
   <origin  rpy="0.0 0.0 0.0"  xyz="0.0 0.0 0.0" />
   <geometry >
    <box  size="0.08 0.08 0.08" />
   </geometry>
  </collision>
  <inertial >
   <origin  rpy="0.0 0.0 0.0"  xyz="0.0 0.0 0.0" />
   <mass  value="0.4937142857142858" />
   <inertia  ixy="0.0"  ixz="0.0"  izz="0.0005266285714285715"  ixx="0.0005266285714285715"  iyz="0.0"  iyy="0.0005266285714285715" />
  </inertial>
 </link>
 <link  name="L3" >
  <visual >
   <origin  rpy="0.0 0.0 0.0"  xyz="0.0 0.0 0.17529" />
   <geometry >
    <box  size="0.04 0.04 0.31057414084143564" />
   </geometry>
   <material  name="L3_Material" >
    <color  rgba="0.6763130730287981 0.4599164986729355 0.6970338286249718 1.0" />
   </material>
  </visual>
  <collision  name="L3_Collision" >
   <origin  rpy="0.0 0.0 0.0"  xyz="0.0 0.0 0.17529" />
   <geometry >
    <box  size="0.04 0.04 0.31057414084143564" />
   </geometry>
  </collision>
  <inertial >
   <origin  rpy="0.0 0.0 0.0"  xyz="0.0 0.0 0.17529" />
   <mass  value="0.47917153158392933" />
   <inertia  ixy="0.0"  ixz="0.0"  izz="0.00012777907508904784"  ixx="0.003915482166290194"  iyz="0.0"  iyy="0.003915482166290194" />
  </inertial>
 </link>
 <link  name="L4" >
  <visual >
   <origin  rpy="0.0 0.7330038377215615 0.0"  xyz="-0.10295216702927151 0.0 0.30094575896599096" />
   <geometry >
    <box  size="0.03999999910593033 0.03999999910593033 0.267730973170762" />
   </geometry>
   <material  name="L4_Material" >
    <color  rgba="0.9848141484811896 0.9577040643002175 0.4573327686707884 1.0" />
   </material>
  </visual>
  <collision  name="L4_0_Collision" >
   <origin  rpy="0.0 0.7330038377215615 0.0"  xyz="-0.10295216702927151 0.0 0.30094575896599096" />
   <geometry >
    <box  size="0.03999999910593033 0.03999999910593033 0.267730973170762" />
   </geometry>
  </collision>
  <visual >
   <origin  rpy="3.141592653589793 0.8345467114834739 3.141592653589793"  xyz="-0.10295216702927368 0.0 0.09329893627333558" />
   <geometry >
    <box  size="0.03999999910593033 0.03999999910593033 0.23787652171408707" />
   </geometry>
   <material  name="L4_Material" >
    <color  rgba="0.9848141484811896 0.9577040643002175 0.4573327686707884 1.0" />
   </material>
  </visual>
  <collision  name="L4_1_Collision" >
   <origin  rpy="3.141592653589793 0.8345467114834739 3.141592653589793"  xyz="-0.10295216702927368 0.0 0.09329893627333558" />
   <geometry >
    <box  size="0.03999999910593033 0.03999999910593033 0.23787652171408707" />
   </geometry>
  </collision>
  <visual >
   <origin  rpy="0.0 -1.354472090042691e-14 0.0"  xyz="2.1649348980190553e-15 0.0 0.20764682269265547" />
   <geometry >
    <box  size="0.03999999910593033 0.03999999910593033 0.3752936462793805" />
   </geometry>
   <material  name="L4_Material" >
    <color  rgba="0.9848141484811896 0.9577040643002175 0.4573327686707884 1.0" />
   </material>
  </visual>
  <collision  name="L4_2_Collision" >
   <origin  rpy="0.0 -1.354472090042691e-14 0.0"  xyz="2.1649348980190553e-15 0.0 0.20764682269265547" />
   <geometry >
    <box  size="0.03999999910593033 0.03999999910593033 0.3752936462793805" />
   </geometry>
  </collision>
  <inertial >
   <origin  rpy="0.0 0.0 0.0"  xyz="-0.06863 0.0 0.20063" />
   <mass  value="1.4538704687140938" />
   <inertia  ixy="-2.364937164557688e-19"  ixz="-0.09211775389102192"  izz="0.09397256977970449"  ixx="0.11650103534364467"  iyz="5.462364220959546e-20"  iyy="0.21008590634902355" />
  </inertial>
 </link>
 <link  name="EE" >
  <visual >
   <origin  rpy="-3.141592653589793 -0.649792184270373 3.141592653589793"  xyz="-0.11403255452305544 0.0 0.2171563243105497" />
   <geometry >
    <box  size="0.03999999910593033 0.03999999910593033 0.3369540676306518" />
   </geometry>
   <material  name="EE_Material" >
    <color  rgba="0.6237624956805166 0.6109011485889799 0.45994442203244756 1.0" />
   </material>
  </visual>
  <collision  name="EE_0_Collision" >
   <origin  rpy="-3.141592653589793 -0.649792184270373 3.141592653589793"  xyz="-0.11403255452305544 0.0 0.2171563243105497" />
   <geometry >
    <box  size="0.03999999910593033 0.03999999910593033 0.3369540676306518" />
   </geometry>
  </collision>
  <visual >
   <origin  rpy="0.0 0.0 0.0"  xyz="0.0 0.0 0.18361176898624476" />
   <geometry >
    <box  size="0.03999999910593033 0.03999999910593033 0.3272235388665592" />
   </geometry>
   <material  name="EE_Material" >
    <color  rgba="0.6237624956805166 0.6109011485889799 0.45994442203244756 1.0" />
   </material>
  </visual>
  <collision  name="EE_1_Collision" >
   <origin  rpy="0.0 0.0 0.0"  xyz="0.0 0.0 0.18361176898624476" />
   <geometry >
    <box  size="0.03999999910593033 0.03999999910593033 0.3272235388665592" />
   </geometry>
  </collision>
  <visual >
   <origin  rpy="3.141592653589793 1.2846999394537875 3.141592653589793"  xyz="-0.11403255452305544 0.0 0.03354455532430495" />
   <geometry >
    <box  size="0.03999999910593033 0.03999999910593033 0.1977280865966973" />
   </geometry>
   <material  name="EE_Material" >
    <color  rgba="0.6237624956805166 0.6109011485889799 0.45994442203244756 1.0" />
   </material>
  </visual>
  <collision  name="EE_2_Collision" >
   <origin  rpy="3.141592653589793 1.2846999394537875 3.141592653589793"  xyz="-0.11403255452305544 0.0 0.03354455532430495" />
   <geometry >
    <box  size="0.03999999910593033 0.03999999910593033 0.1977280865966973" />
   </geometry>
  </collision>
  <inertial >
   <origin  rpy="0.0 0.0 0.0"  xyz="-0.07602 0.0 0.14477" />
   <mass  value="1.426133416782204" />
   <inertia  ixy="1.0786937357224497e-18"  ixz="-0.39848481483425074"  izz="0.2754588958315214"  ixx="0.6219526497763233"  iyz="2.3751605497192806e-19"  iyy="0.8970312433803701" />
  </inertial>
 </link>
 <link  name="L7" >
  <visual >
   <origin  rpy="0.0 0.0 0.0"  xyz="0.0 0.0 0.16301" />
   <geometry >
    <box  size="0.04 0.04 0.2860298385684489" />
   </geometry>
   <material  name="L7_Material" >
    <color  rgba="0.5977254977176822 0.9095280961245363 0.9156368867524194 1.0" />
   </material>
  </visual>
  <collision  name="L7_Collision" >
   <origin  rpy="0.0 0.0 0.0"  xyz="0.0 0.0 0.16301" />
   <geometry >
    <box  size="0.04 0.04 0.2860298385684489" />
   </geometry>
  </collision>
  <inertial >
   <origin  rpy="0.0 0.0 0.0"  xyz="0.0 0.0 0.16301" />
   <mass  value="0.4413031795056069" />
   <inertia  ixy="0.0"  ixz="0.0"  izz="0.00011768084786816183"  ixx="0.0030675376970077475"  iyz="0.0"  iyy="0.0030675376970077475" />
  </inertial>
 </link>
 <link  name="L5" >
  <visual >
   <origin  rpy="-3.141592653589793 -0.9372251978037345 3.141592653589793"  xyz="0.13890486792042905 0.0 0.10203932178788488" />
   <geometry >
    <box  size="0.03999999910593033 0.03999999910593033 0.30471197064808536" />
   </geometry>
   <material  name="L5_Material" >
    <color  rgba="0.7685646578926987 0.6574272940531629 0.26118625981612986 1.0" />
   </material>
  </visual>
  <collision  name="L5_0_Collision" >
   <origin  rpy="-3.141592653589793 -0.9372251978037345 3.141592653589793"  xyz="0.13890486792042905 0.0 0.10203932178788488" />
   <geometry >
    <box  size="0.03999999910593033 0.03999999910593033 0.30471197064808536" />
   </geometry>
  </collision>
  <visual >
   <origin  rpy="0.0 -1.0072807061778266 0.0"  xyz="0.13890486792042905 0.0 0.2918467767704922" />
   <geometry >
    <box  size="0.03999999910593033 0.03999999910593033 0.2886201922182084" />
   </geometry>
   <material  name="L5_Material" >
    <color  rgba="0.7685646578926987 0.6574272940531629 0.26118625981612986 1.0" />
   </material>
  </visual>
  <collision  name="L5_1_Collision" >
   <origin  rpy="0.0 -1.0072807061778266 0.0"  xyz="0.13890486792042905 0.0 0.2918467767704922" />
   <geometry >
    <box  size="0.03999999910593033 0.03999999910593033 0.2886201922182084" />
   </geometry>
  </collision>
  <visual >
   <origin  rpy="0.0 0.0 0.0"  xyz="0.0 0.0 0.18980745498260734" />
   <geometry >
    <box  size="0.03999999910593033 0.03999999910593033 0.33961491085928436" />
   </geometry>
   <material  name="L5_Material" >
    <color  rgba="0.7685646578926987 0.6574272940531629 0.26118625981612986 1.0" />
   </material>
  </visual>
  <collision  name="L5_2_Collision" >
   <origin  rpy="0.0 0.0 0.0"  xyz="0.0 0.0 0.18980745498260734" />
   <geometry >
    <box  size="0.03999999910593033 0.03999999910593033 0.33961491085928436" />
   </geometry>
  </collision>
  <inertial >
   <origin  rpy="0.0 0.0 0.0"  xyz="0.0926 0.0 0.19456" />
   <mass  value="1.5434473348983349" />
   <inertia  ixy="2.178084721511058e-19"  ixz="0.10532983332664972"  izz="0.10702578190605617"  ixx="0.1403818190296316"  iyz="-2.178084721511058e-19"  iyy="0.24699601499811424" />
  </inertial>
 </link>
 <link  name="L6" >
  <visual >
   <origin  rpy="0.0 0.0 0.0"  xyz="0.0 0.0 0.22699" />
   <geometry >
    <box  size="0.04 0.04 0.41398223209157115" />
   </geometry>
   <material  name="L6_Material" >
    <color  rgba="0.08047573790350548 0.5922119917180177 0.9142307459094781 1.0" />
   </material>
  </visual>
  <collision  name="L6_Collision" >
   <origin  rpy="0.0 0.0 0.0"  xyz="0.0 0.0 0.22699" />
   <geometry >
    <box  size="0.04 0.04 0.41398223209157115" />
   </geometry>
  </collision>
  <inertial >
   <origin  rpy="0.0 0.0 0.0"  xyz="0.0 0.0 0.22699" />
   <mass  value="0.6387154437984242" />
   <inertia  ixy="0.0"  ixz="0.0"  izz="0.00017032411834624645"  ixx="0.00920715170376077"  iyz="0.0"  iyy="0.00920715170376077" />
  </inertial>
 </link>
 <joint  type="revolute"  name="Gabs" >
  <parent  link="G" />
  <child  link="L3" />
  <origin  rpy="0.0 0.7547270559595018 0.0"  xyz="0.0 0.0 0.0" />
  <axis  xyz="0 1 0" />
  <limit  lower="-3.141592653589793"  upper="3.141592653589793"  velocity="18.692476288859268"  effort="120.6" />
  <dynamics  damping="0.05"  friction="0" />
 </joint>
 <joint  type="fixed"  name="Gabs_G_WeldActuator" >
  <parent  link="G" />
  <child  link="Gabs_GActuator" />
  <origin  rpy="1.5707963267948966 0.7547270559595018 1.1102230246251565e-16"  xyz="0.0 0.0775 0.0" />
 </joint>
 <link  name="Gabs_GActuator" >
  <visual >
   <geometry >
    <cylinder  radius="0.06"  length="0.075" />
   </geometry>
   <material  name="Gabs_GActuator_Material" >
    <color  rgba="0.20856352241202425 0.6597387408684208 0.8100469130840032 0.9" />
   </material>
  </visual>
  <inertial >
   <inertia  ixy="0.0"  ixz="0.0"  izz="0.066"  ixx="0.04675"  iyz="0.0"  iyy="0.04675" />
   <mass  value="2.2" />
  </inertial>
 </link>
 <link  name="Gabs_GUnit" >
  <visual >
   <geometry >
    <cylinder  radius="0.04"  length="0.08" />
   </geometry>
   <material  name="Gabs_GUnit_Material" >
    <color  rgba="0.20856352241202425 0.6597387408684208 0.8100469130840032 0.9" />
   </material>
  </visual>
  <inertial >
   <inertia  ixy="0.0"  ixz="0.0"  izz="0.002"  ixx="0.0016666666666666666"  iyz="0.0"  iyy="0.0016666666666666666" />
   <mass  value="0.1" />
  </inertial>
 </link>
 <joint  type="fixed"  name="Gabs_G_WeldUnit" >
  <parent  link="G" />
  <child  link="Gabs_GUnit" />
  <origin  rpy="1.5707963267948966 0.7547270559595018 1.1102230246251565e-16"  xyz="0.0 0.0 0.0" />
 </joint>
 <joint  type="revolute"  name="J1m" >
  <parent  link="L3" />
  <child  link="L4" />
  <origin  rpy="0.0 -0.7678841914322679 0.0"  xyz="1.220686378567705e-17 0.0 0.35057414084143557" />
  <axis  xyz="0 1 0" />
  <limit  lower="-3.141592653589793"  upper="3.141592653589793"  velocity="18.692476288859268"  effort="28.799999999999997" />
  <dynamics  damping="0.05"  friction="0" />
 </joint>
 <joint  type="fixed"  name="J1m_L3_WeldActuator" >
  <parent  link="L3" />
  <child  link="J1m_L3Actuator" />
  <origin  rpy="1.5707963267948966 -0.7678841914322678 -1.1102230246251565e-16"  xyz="1.220686378567705e-17 0.051000000000000004 0.35057414084143557" />
 </joint>
 <link  name="J1m_L3Actuator" >
  <visual >
   <geometry >
    <cylinder  radius="0.045"  length="0.062" />
   </geometry>
   <material  name="J1m_L3Actuator_Material" >
    <color  rgba="0.6763130730287981 0.4599164986729355 0.6970338286249718 0.9" />
   </material>
  </visual>
  <inertial >
   <inertia  ixy="0.0"  ixz="0.0"  izz="0.021599999999999998"  ixx="0.015759999999999996"  iyz="0.0"  iyy="0.015759999999999996" />
   <mass  value="0.96" />
  </inertial>
 </link>
 <link  name="J1m_L3Unit" >
  <visual >
   <geometry >
    <cylinder  radius="0.02"  length="0.04" />
   </geometry>
   <material  name="J1m_L3Unit_Material" >
    <color  rgba="0.6763130730287981 0.4599164986729355 0.6970338286249718 0.9" />
   </material>
  </visual>
  <inertial >
   <inertia  ixy="0.0"  ixz="0.0"  izz="0.001"  ixx="0.0008333333333333333"  iyz="0.0"  iyy="0.0008333333333333333" />
   <mass  value="0.1" />
  </inertial>
 </link>
 <joint  type="fixed"  name="J1m_L3_WeldUnit" >
  <parent  link="L3" />
  <child  link="J1m_L3Unit" />
  <origin  rpy="1.5707963267948966 -0.7678841914322678 -1.1102230246251565e-16"  xyz="1.220686378567705e-17 0.0 0.35057414084143557" />
 </joint>
 <joint  type="revolute"  name="J2m" >
  <parent  link="L4" />
  <child  link="EE" />
  <origin  rpy="0.0 1.15850382489762 0.0"  xyz="4.3298697960381105e-15 0.0 0.4152936453853109" />
  <axis  xyz="0 1 0" />
  <limit  lower="-3.141592653589793"  upper="3.141592653589793"  velocity="6.283185307179586"  effort="600.0" />
  <dynamics  damping="0.05"  friction="0" />
 </joint>
 <link  name="J2m_L4Unit" >
  <visual >
   <geometry >
    <cylinder  radius="0.019999999552965164"  length="0.03999999910593033" />
   </geometry>
   <material  name="J2m_L4Unit_Material" >
    <color  rgba="0.9848141484811896 0.9577040643002175 0.4573327686707884 0.9" />
   </material>
  </visual>
  <inertial >
   <inertia  ixy="0.0"  ixz="0.0"  izz="0.0009999999776482583"  ixx="0.0008333333147068819"  iyz="0.0"  iyy="0.0008333333147068819" />
   <mass  value="0.1" />
  </inertial>
 </link>
 <joint  type="fixed"  name="J2m_L4_WeldUnit" >
  <parent  link="L4" />
  <child  link="J2m_L4Unit" />
  <origin  rpy="1.5707963267948966 1.1585038248976205 1.1102230246251565e-16"  xyz="4.3298697960381105e-15 0.0 0.4152936453853109" />
 </joint>
 <joint  type="revolute"  name="G2" >
  <parent  link="G" />
  <child  link="L7" />
  <origin  rpy="0.0 0.28510567942682874 0.0"  xyz="-0.380573704570364 0.0 0.0" />
  <axis  xyz="0 1 0" />
  <limit  lower="-3.141592653589793"  upper="3.141592653589793"  velocity="6.283185307179586"  effort="600.0" />
  <dynamics  damping="0.05"  friction="0" />
 </joint>
 <link  name="G2_GUnit" >
  <visual >
   <geometry >
    <cylinder  radius="0.04"  length="0.08" />
   </geometry>
   <material  name="G2_GUnit_Material" >
    <color  rgba="0.20856352241202425 0.6597387408684208 0.8100469130840032 0.9" />
   </material>
  </visual>
  <inertial >
   <inertia  ixy="0.0"  ixz="0.0"  izz="0.002"  ixx="0.0016666666666666666"  iyz="0.0"  iyy="0.0016666666666666666" />
   <mass  value="0.1" />
  </inertial>
 </link>
 <joint  type="fixed"  name="G2_G_WeldUnit" >
  <parent  link="G" />
  <child  link="G2_GUnit" />
  <origin  rpy="1.5707963267948966 0.28510567942682874 -1.1102230246251565e-16"  xyz="-0.380573704570364 0.0 0.0" />
 </joint>
 <joint  type="revolute"  name="J1b1" >
  <parent  link="L7" />
  <child  link="L5" />
  <origin  rpy="0.0 -0.026921955112104046 0.0"  xyz="-1.1102230246251565e-16 0.0 0.32602983856844886" />
  <axis  xyz="0 1 0" />
  <limit  lower="-3.141592653589793"  upper="3.141592653589793"  velocity="6.283185307179586"  effort="600.0" />
  <dynamics  damping="0.05"  friction="0" />
 </joint>
 <link  name="J1b1_L7Unit" >
  <visual >
   <geometry >
    <cylinder  radius="0.02"  length="0.04" />
   </geometry>
   <material  name="J1b1_L7Unit_Material" >
    <color  rgba="0.5977254977176822 0.9095280961245363 0.9156368867524194 0.9" />
   </material>
  </visual>
  <inertial >
   <inertia  ixy="0.0"  ixz="0.0"  izz="0.001"  ixx="0.0008333333333333333"  iyz="0.0"  iyy="0.0008333333333333333" />
   <mass  value="0.1" />
  </inertial>
 </link>
 <joint  type="fixed"  name="J1b1_L7_WeldUnit" >
  <parent  link="L7" />
  <child  link="J1b1_L7Unit" />
  <origin  rpy="1.5707963267948966 -0.026921955112104046 0.0"  xyz="-1.1102230246251565e-16 0.0 0.32602983856844886" />
 </joint>
 <link  name="J2b1_L5Pseudo" >
  <visual >
   <geometry >
    <sphere  radius="0.02857142793280738" />
   </geometry>
   <material  name="J2b1_L5Pseudo_Material" >
    <color  rgba="0.7685646578926987 0.6574272940531629 0.26118625981612986 0.5" />
   </material>
  </visual>
  <inertial >
   <mass  value="0.05" />
   <inertia  ixy="0.0"  ixz="0.0"  izz="1.632652988239212e-05"  ixx="1.632652988239212e-05"  iyz="0.0"  iyy="1.632652988239212e-05" />
  </inertial>
 </link>
 <joint  type="revolute"  name="J2b1_L5_revolute" >
  <parent  link="L5" />
  <child  link="J2b1_L5Pseudo" />
  <origin  rpy="0.0 0.0 0.0"  xyz="0.2778097358408581 0.0 0.20407864357576977" />
  <axis  xyz="0 1 0" />
  <limit  lower="-3.141592653589793"  upper="3.141592653589793"  velocity="6.283185307179586"  effort="600.0" />
  <dynamics  damping="0.05"  friction="0" />
 </joint>
 <joint  type="fixed"  name="J2b1_L5_Weld" >
  <parent  link="L4" />
  <child  link="J2b1_L4Pseudo" />
  <origin  rpy="0.0 0.2713408597874907 0.0"  xyz="-0.2059043340585472 0.0 0.1865978725466711" />
 </joint>
 <link  name="J2b1_L4Pseudo" >
  <visual >
   <geometry >
    <sphere  radius="0.02857142793280738" />
   </geometry>
   <material  name="J2b1_L4Pseudo_Material" >
    <color  rgba="0.9848141484811896 0.9577040643002175 0.4573327686707884 0.5" />
   </material>
  </visual>
  <inertial >
   <mass  value="0.05" />
   <inertia  ixy="0.0"  ixz="0.0"  izz="1.632652988239212e-05"  ixx="1.632652988239212e-05"  iyz="0.0"  iyy="1.632652988239212e-05" />
  </inertial>
 </link>
 <joint  type="revolute"  name="J1b2" >
  <parent  link="L5" />
  <child  link="L6" />
  <origin  rpy="0.0 0.7911298922393737 0.0"  xyz="0.0 0.0 0.3796149099652147" />
  <axis  xyz="0 1 0" />
  <limit  lower="-3.141592653589793"  upper="3.141592653589793"  velocity="6.283185307179586"  effort="600.0" />
  <dynamics  damping="0.05"  friction="0" />
 </joint>
 <link  name="J1b2_L5Unit" >
  <visual >
   <geometry >
    <cylinder  radius="0.019999999552965164"  length="0.03999999910593033" />
   </geometry>
   <material  name="J1b2_L5Unit_Material" >
    <color  rgba="0.7685646578926987 0.6574272940531629 0.26118625981612986 0.9" />
   </material>
  </visual>
  <inertial >
   <inertia  ixy="0.0"  ixz="0.0"  izz="0.0009999999776482583"  ixx="0.0008333333147068819"  iyz="0.0"  iyy="0.0008333333147068819" />
   <mass  value="0.1" />
  </inertial>
 </link>
 <joint  type="fixed"  name="J1b2_L5_WeldUnit" >
  <parent  link="L5" />
  <child  link="J1b2_L5Unit" />
  <origin  rpy="1.5707963267948966 0.7911298922393732 1.1102230246251565e-16"  xyz="0.0 0.0 0.3796149099652147" />
 </joint>
 <link  name="J2b2_L6Pseudo" >
  <visual >
   <geometry >
    <sphere  radius="0.028571428571428574" />
   </geometry>
   <material  name="J2b2_L6Pseudo_Material" >
    <color  rgba="0.08047573790350548 0.5922119917180177 0.9142307459094781 0.5" />
   </material>
  </visual>
  <inertial >
   <mass  value="0.05" />
   <inertia  ixy="0.0"  ixz="0.0"  izz="1.6326530612244903e-05"  ixx="1.6326530612244903e-05"  iyz="0.0"  iyy="1.6326530612244903e-05" />
  </inertial>
 </link>
 <joint  type="revolute"  name="J2b2_L6_revolute" >
  <parent  link="L6" />
  <child  link="J2b2_L6Pseudo" />
  <origin  rpy="0.0 0.0 0.0"  xyz="1.1102230246251565e-16 0.0 0.45398223209157107" />
  <axis  xyz="0 1 0" />
  <limit  lower="-3.141592653589793"  upper="3.141592653589793"  velocity="6.283185307179586"  effort="600.0" />
  <dynamics  damping="0.05"  friction="0" />
 </joint>
 <joint  type="fixed"  name="J2b2_L6_Weld" >
  <parent  link="EE" />
  <child  link="J2b2_EEPseudo" />
  <origin  rpy="0.0 -0.09603307287075635 0.0"  xyz="-0.22806510904611083 0.0 0.06708911064860973" />
 </joint>
 <link  name="J2b2_EEPseudo" >
  <visual >
   <geometry >
    <sphere  radius="0.02857142793280738" />
   </geometry>
   <material  name="J2b2_EEPseudo_Material" >
    <color  rgba="0.6237624956805166 0.6109011485889799 0.45994442203244756 0.5" />
   </material>
  </visual>
  <inertial >
   <mass  value="0.05" />
   <inertia  ixy="0.0"  ixz="0.0"  izz="1.632652988239212e-05"  ixx="1.632652988239212e-05"  iyz="0.0"  iyy="1.632652988239212e-05" />
  </inertial>
 </link>
</robot>
