<?xml version="1.0"?>
<robot  name="Robot" >
 <link  name="L21611" >
  <visual >
   <origin  xyz="-6.30118608483749e-05 0.0 0.1742996075171044"  rpy="0.0 -0.0003615146297732963 0.0" />
   <geometry >
    <box  size="0.03999999910593033 0.03999999910593033 0.3085992387079883" />
   </geometry>
   <material  name="L21611_Material" >
    <color  rgba="0.5939270336084382 0.6126896595828943 0.2958272939731498 1.0" />
   </material>
  </visual>
  <collision  name="L21611_0_Collision" >
   <origin  xyz="-6.30118608483749e-05 0.0 0.1742996075171044"  rpy="0.0 -0.0003615146297732963 0.0" />
   <geometry >
    <box  size="0.03999999910593033 0.03999999910593033 0.3085992387079883" />
   </geometry>
  </collision>
  <visual >
   <origin  xyz="-1.3877787807814457e-17 0.0 0.28867513459481287"  rpy="0.0 0.0 0.0" />
   <geometry >
    <box  size="0.03999999910593033 0.03999999910593033 0.5373502700836954" />
   </geometry>
   <material  name="L21611_Material" >
    <color  rgba="0.5939270336084382 0.6126896595828943 0.2958272939731498 1.0" />
   </material>
  </visual>
  <collision  name="L21611_1_Collision" >
   <origin  xyz="-1.3877787807814457e-17 0.0 0.28867513459481287"  rpy="0.0 0.0 0.0" />
   <geometry >
    <box  size="0.03999999910593033 0.03999999910593033 0.5373502700836954" />
   </geometry>
  </collision>
  <visual >
   <origin  xyz="-6.301186084838877e-05 0.0 0.46297474211191725"  rpy="0.0 0.0005509207790064252 0.0" />
   <geometry >
    <box  size="0.03999999910593033 0.03999999910593033 0.18875108976403093" />
   </geometry>
   <material  name="L21611_Material" >
    <color  rgba="0.5939270336084382 0.6126896595828943 0.2958272939731498 1.0" />
   </material>
  </visual>
  <collision  name="L21611_2_Collision" >
   <origin  xyz="-6.301186084838877e-05 0.0 0.46297474211191725"  rpy="0.0 0.0005509207790064252 0.0" />
   <geometry >
    <box  size="0.03999999910593033 0.03999999910593033 0.18875108976403093" />
   </geometry>
  </collision>
  <inertial >
   <origin  xyz="-4e-05 0.0 0.30865"  rpy="0.0 0.0 0.0" />
   <mass  value="0.8921791967904164" />
   <inertia  iyy="0.32194418672004327"  izz="0.025008608624271164"  ixz="0.08265514981976187"  iyz="1.3552053965822152e-10"  ixx="0.2971734925381584"  ixy="-4.982234974145852e-11" />
  </inertial>
 </link>
 <link  name="G" >
  <visual >
   <origin  xyz="0.0 0.0 0.0"  rpy="0.0 0.0 0.0" />
   <geometry >
    <box  size="0.08 0.08 0.08" />
   </geometry>
   <material  name="G_Material" >
    <color  rgba="0.9691119426182628 0.7475000981902138 0.802280616086089 1.0" />
   </material>
  </visual>
  <collision  name="G_Collision" >
   <origin  xyz="0.0 0.0 0.0"  rpy="0.0 0.0 0.0" />
   <geometry >
    <box  size="0.08 0.08 0.08" />
   </geometry>
  </collision>
  <inertial >
   <origin  xyz="0.0 0.0 0.0"  rpy="0.0 0.0 0.0" />
   <mass  value="0.4937142857142858" />
   <inertia  iyy="0.0005266285714285715"  izz="0.0005266285714285715"  ixz="0.0"  iyz="0.0"  ixx="0.0005266285714285715"  ixy="0.0" />
  </inertial>
 </link>
 <link  name="L21612" >
  <visual >
   <origin  xyz="2.7755575615628914e-17 0.0 0.28867513459481287"  rpy="0.0 0.0 0.0" />
   <geometry >
    <box  size="0.03999999910593033 0.03999999910593033 0.5373502700836954" />
   </geometry>
   <material  name="L21612_Material" >
    <color  rgba="0.03507239608413104 0.4595935723768264 0.9333413070384142 1.0" />
   </material>
  </visual>
  <collision  name="L21612_0_Collision" >
   <origin  xyz="2.7755575615628914e-17 0.0 0.28867513459481287"  rpy="0.0 0.0 0.0" />
   <geometry >
    <box  size="0.03999999910593033 0.03999999910593033 0.5373502700836954" />
   </geometry>
  </collision>
  <visual >
   <origin  xyz="9.223931862031853e-05 0.0 0.4561069042035054"  rpy="3.141592653589793 0.000760778132684603 3.141592653589793" />
   <geometry >
    <box  size="0.03999999910593033 0.03999999910593033 0.20248680103997027" />
   </geometry>
   <material  name="L21612_Material" >
    <color  rgba="0.03507239608413104 0.4595935723768264 0.9333413070384142 1.0" />
   </material>
  </visual>
  <collision  name="L21612_1_Collision" >
   <origin  xyz="9.223931862031853e-05 0.0 0.4561069042035054"  rpy="3.141592653589793 0.000760778132684603 3.141592653589793" />
   <geometry >
    <box  size="0.03999999910593033 0.03999999910593033 0.20248680103997027" />
   </geometry>
  </collision>
  <visual >
   <origin  xyz="9.223931862029078e-05 0.0 0.16743176960869255"  rpy="0.0 0.0005509068530993311 0.0" />
   <geometry >
    <box  size="0.03999999910593033 0.03999999910593033 0.2948635909267288" />
   </geometry>
   <material  name="L21612_Material" >
    <color  rgba="0.03507239608413104 0.4595935723768264 0.9333413070384142 1.0" />
   </material>
  </visual>
  <collision  name="L21612_2_Collision" >
   <origin  xyz="9.223931862029078e-05 0.0 0.16743176960869255"  rpy="0.0 0.0005509068530993311 0.0" />
   <geometry >
    <box  size="0.03999999910593033 0.03999999910593033 0.2948635909267288" />
   </geometry>
  </collision>
  <inertial >
   <origin  xyz="6e-05 0.0 0.30407"  rpy="0.0 0.0 0.0" />
   <mass  value="0.8928267049839939" />
   <inertia  iyy="1.035466271998057"  izz="0.024972770385654396"  ixz="0.1250503383085419"  iyz="1.2557267421918618e-07"  ixx="1.0107315853387506"  ixy="-2.1906006343951932e-08" />
  </inertial>
 </link>
 <link  name="EE" >
  <visual >
   <origin  xyz="0.0 0.0 0.0"  rpy="0.0 0.0 0.0" />
   <geometry >
    <sphere  radius="0.028571428571428574" />
   </geometry>
   <material  name="EE_Material" >
    <color  rgba="0.6626769210112649 0.5312339672915674 0.4460832332150346 1.0" />
   </material>
  </visual>
  <collision  name="EE_Collision" >
   <origin  xyz="0.0 0.0 0.0"  rpy="0.0 0.0 0.0" />
   <geometry >
    <sphere  radius="0.028571428571428574" />
   </geometry>
  </collision>
  <inertial >
   <origin  xyz="0.0 0.0 0.0"  rpy="0.0 0.0 0.0" />
   <mass  value="0.09420852605517083" />
   <inertia  iyy="3.0761967691484357e-05"  izz="3.0761967691484357e-05"  ixz="0.0"  iyz="0.0"  ixx="3.0761967691484357e-05"  ixy="0.0" />
  </inertial>
 </link>
 <link  name="L21614" >
  <visual >
   <origin  xyz="0.0 0.0 0.06489"  rpy="0.0 0.0 0.0" />
   <geometry >
    <box  size="0.04 0.04 0.08977972884138244" />
   </geometry>
   <material  name="L21614_Material" >
    <color  rgba="0.8865138098454768 0.9791489879898532 0.9405348755563504 1.0" />
   </material>
  </visual>
  <collision  name="L21614_Collision" >
   <origin  xyz="0.0 0.0 0.06489"  rpy="0.0 0.0 0.0" />
   <geometry >
    <box  size="0.04 0.04 0.08977972884138244" />
   </geometry>
  </collision>
  <inertial >
   <origin  xyz="0.0 0.0 0.06489"  rpy="0.0 0.0 0.0" />
   <mass  value="0.13851729592670436" />
   <inertia  iyy="0.00011151103712629894"  izz="3.6937945580454495e-05"  ixz="0.0"  iyz="0.0"  ixx="0.00011151103712629894"  ixy="0.0" />
  </inertial>
 </link>
 <link  name="L21613" >
  <visual >
   <origin  xyz="0.0 0.0 0.06144989867021398"  rpy="0.0 0.0 0.0" />
   <geometry >
    <box  size="0.03999999910593033 0.03999999910593033 0.08289979823449765" />
   </geometry>
   <material  name="L21613_Material" >
    <color  rgba="0.28210517399101764 0.698724604126502 0.6638692433356483 1.0" />
   </material>
  </visual>
  <collision  name="L21613_0_Collision" >
   <origin  xyz="0.0 0.0 0.06144989867021398"  rpy="0.0 0.0 0.0" />
   <geometry >
    <box  size="0.03999999910593033 0.03999999910593033 0.08289979823449765" />
   </geometry>
  </collision>
  <visual >
   <origin  xyz="0.0002962163149772684 0.0 0.4095422795575895"  rpy="0.0 0.0010333995409268493 0.0" />
   <geometry >
    <box  size="0.03999999910593033 0.03999999910593033 0.5332852714382238" />
   </geometry>
   <material  name="L21613_Material" >
    <color  rgba="0.28210517399101764 0.698724604126502 0.6638692433356483 1.0" />
   </material>
  </visual>
  <collision  name="L21613_1_Collision" >
   <origin  xyz="0.0002962163149772684 0.0 0.4095422795575895"  rpy="0.0 0.0010333995409268493 0.0" />
   <geometry >
    <box  size="0.03999999910593033 0.03999999910593033 0.5332852714382238" />
   </geometry>
  </collision>
  <visual >
   <origin  xyz="0.0002962163149772684 0.0 0.3480923808873755"  rpy="0.0 0.000850970201413892 0.0" />
   <geometry >
    <box  size="0.03999999910593033 0.03999999910593033 0.656185014740093" />
   </geometry>
   <material  name="L21613_Material" >
    <color  rgba="0.28210517399101764 0.698724604126502 0.6638692433356483 1.0" />
   </material>
  </visual>
  <collision  name="L21613_2_Collision" >
   <origin  xyz="0.0002962163149772684 0.0 0.3480923808873755"  rpy="0.0 0.000850970201413892 0.0" />
   <geometry >
    <box  size="0.03999999910593033 0.03999999910593033 0.656185014740093" />
   </geometry>
  </collision>
  <inertial >
   <origin  xyz="0.0002 0.0 0.27303"  rpy="0.0 0.0 0.0" />
   <mass  value="1.0755240525510366" />
   <inertia  iyy="0.6230187380531027"  izz="0.00498517355464749"  ixz="0.01875226079602316"  iyz="-9.437754077177643e-09"  ixx="0.6183203706519558"  ixy="8.265735144602748e-10" />
  </inertial>
 </link>
 <link  name="L21615" >
  <visual >
   <origin  xyz="0.0 0.0 0.02905"  rpy="0.0 0.0 0.0" />
   <geometry >
    <box  size="0.04 0.04 0.018104307087678823" />
   </geometry>
   <material  name="L21615_Material" >
    <color  rgba="0.3867408324893238 0.6010126359204915 0.5540397028842515 1.0" />
   </material>
  </visual>
  <collision  name="L21615_Collision" >
   <origin  xyz="0.0 0.0 0.02905"  rpy="0.0 0.0 0.0" />
   <geometry >
    <box  size="0.04 0.04 0.018104307087678823" />
   </geometry>
  </collision>
  <inertial >
   <origin  xyz="0.0 0.0 0.02905"  rpy="0.0 0.0 0.0" />
   <mass  value="0.027932359506704474" />
   <inertia  iyy="4.4872542620574345e-06"  izz="7.44862920178786e-06"  ixz="0.0"  iyz="0.0"  ixx="4.4872542620574345e-06"  ixy="0.0" />
  </inertial>
 </link>
 <link  name="L21616" >
  <visual >
   <origin  xyz="-0.0 0.0 0.09665"  rpy="0.0 0.0 0.0" />
   <geometry >
    <box  size="0.04 0.04 0.15330986291309978" />
   </geometry>
   <material  name="L21616_Material" >
    <color  rgba="0.6536178921448756 0.33449775732404274 0.45724544805313605 1.0" />
   </material>
  </visual>
  <collision  name="L21616_Collision" >
   <origin  xyz="-0.0 0.0 0.09665"  rpy="0.0 0.0 0.0" />
   <geometry >
    <box  size="0.04 0.04 0.15330986291309978" />
   </geometry>
  </collision>
  <inertial >
   <origin  xyz="-0.0 0.0 0.09665"  rpy="0.0 0.0 0.0" />
   <mass  value="0.23653521706592542" />
   <inertia  iyy="0.0004948299802423478"  izz="6.307605788424677e-05"  ixz="0.0"  iyz="0.0"  ixx="0.0004948299802423478"  ixy="0.0" />
  </inertial>
 </link>
 <joint  type="revolute"  name="TL_ground" >
  <parent  link="G" />
  <child  link="L21611" />
  <origin  xyz="0.0 0.0 0.0"  rpy="3.141592653589793 0.5235987755982991 3.141592653589793" />
  <axis  xyz="0 1 0" />
  <limit  effort="10.799999999999999"  lower="-3.141592653589793"  upper="3.141592653589793"  velocity="29.845130209103036" />
  <dynamics  friction="0"  damping="0.05" />
 </joint>
 <joint  type="fixed"  name="TL_ground_G_WeldActuator" >
  <parent  link="G" />
  <child  link="TL_ground_GActuator" />
  <origin  xyz="0.0 0.05925 0.0"  rpy="-1.5707963267948966 0.5235987755982991 -3.141592653589793" />
 </joint>
 <link  name="TL_ground_GActuator" >
  <visual >
   <geometry >
    <cylinder  length="0.0385"  radius="0.0425" />
   </geometry>
   <material  name="TL_ground_GActuator_Material" >
    <color  rgba="0.9691119426182628 0.7475000981902138 0.802280616086089 0.9" />
   </material>
  </visual>
  <inertial >
   <inertia  iyy="0.006709166666666667"  izz="0.010306250000000001"  ixz="0.0"  iyz="0.0"  ixx="0.006709166666666667"  ixy="0.0" />
   <mass  value="0.1" />
  </inertial>
 </link>
 <link  name="TL_ground_GUnit" >
  <visual >
   <geometry >
    <cylinder  length="0.08"  radius="0.04" />
   </geometry>
   <material  name="TL_ground_GUnit_Material" >
    <color  rgba="0.9691119426182628 0.7475000981902138 0.802280616086089 0.9" />
   </material>
  </visual>
  <inertial >
   <inertia  iyy="0.0016666666666666666"  izz="0.002"  ixz="0.0"  iyz="0.0"  ixx="0.0016666666666666666"  ixy="0.0" />
   <mass  value="0.1" />
  </inertial>
 </link>
 <joint  type="fixed"  name="TL_ground_G_WeldUnit" >
  <parent  link="G" />
  <child  link="TL_ground_GUnit" />
  <origin  xyz="0.0 0.0 0.0"  rpy="-1.5707963267948966 0.5235987755982991 -3.141592653589793" />
 </joint>
 <joint  type="revolute"  name="TL_knee" >
  <parent  link="L21611" />
  <child  link="L21612" />
  <origin  xyz="-2.7755575615628914e-17 0.0 0.5773502691896257"  rpy="0.0 1.0471975511965979 0.0" />
  <axis  xyz="0 1 0" />
  <limit  effort="600.0"  lower="-3.141592653589793"  upper="3.141592653589793"  velocity="6.283185307179586" />
  <dynamics  friction="0"  damping="0.05" />
 </joint>
 <link  name="TL_knee_L21611Unit" >
  <visual >
   <geometry >
    <cylinder  length="0.03999999910593033"  radius="0.019999999552965164" />
   </geometry>
   <material  name="TL_knee_L21611Unit_Material" >
    <color  rgba="0.5939270336084382 0.6126896595828943 0.2958272939731498 0.9" />
   </material>
  </visual>
  <inertial >
   <inertia  iyy="0.0008333333147068819"  izz="0.0009999999776482583"  ixz="0.0"  iyz="0.0"  ixx="0.0008333333147068819"  ixy="0.0" />
   <mass  value="0.1" />
  </inertial>
 </link>
 <joint  type="fixed"  name="TL_knee_L21611_WeldUnit" >
  <parent  link="L21611" />
  <child  link="TL_knee_L21611Unit" />
  <origin  xyz="-2.7755575615628914e-17 0.0 0.5773502691896257"  rpy="1.5707963267948961 1.0471975511965979 -2.220446049250313e-16" />
 </joint>
 <joint  type="revolute"  name="TL_ee" >
  <parent  link="L21612" />
  <child  link="EE" />
  <origin  xyz="5.551115123125783e-17 0.0 0.5773502691896257"  rpy="3.141592653589793 0.5235987755982991 3.141592653589793" />
  <axis  xyz="0 1 0" />
  <limit  effort="600.0"  lower="-3.141592653589793"  upper="3.141592653589793"  velocity="6.283185307179586" />
  <dynamics  friction="0"  damping="0.05" />
 </joint>
 <link  name="TL_ee_L21612Unit" >
  <visual >
   <geometry >
    <cylinder  length="0.03999999910593033"  radius="0.019999999552965164" />
   </geometry>
   <material  name="TL_ee_L21612Unit_Material" >
    <color  rgba="0.03507239608413104 0.4595935723768264 0.9333413070384142 0.9" />
   </material>
  </visual>
  <inertial >
   <inertia  iyy="0.0008333333147068819"  izz="0.0009999999776482583"  ixz="0.0"  iyz="0.0"  ixx="0.0008333333147068819"  ixy="0.0" />
   <mass  value="0.1" />
  </inertial>
 </link>
 <joint  type="fixed"  name="TL_ee_L21612_WeldUnit" >
  <parent  link="L21612" />
  <child  link="TL_ee_L21612Unit" />
  <origin  xyz="5.551115123125783e-17 0.0 0.5773502691896257"  rpy="-1.5707963267948966 0.5235987755982991 -3.141592653589793" />
 </joint>
 <joint  type="revolute"  name="FL_branch_ground" >
  <parent  link="G" />
  <child  link="L21614" />
  <origin  xyz="-0.10455651297933616 0.0 -0.002428905253078108"  rpy="3.141592653589793 -0.019670880781618605 3.141592653589793" />
  <axis  xyz="0 1 0" />
  <limit  effort="10.799999999999999"  lower="-3.141592653589793"  upper="3.141592653589793"  velocity="29.845130209103036" />
  <dynamics  friction="0"  damping="0.05" />
 </joint>
 <joint  type="fixed"  name="FL_branch_ground_G_WeldActuator" >
  <parent  link="G" />
  <child  link="FL_branch_ground_GActuator" />
  <origin  xyz="-0.10455651297933616 0.05925 -0.002428905253078108"  rpy="-1.5707963267948966 -0.019670880781618605 -3.141592653589793" />
 </joint>
 <link  name="FL_branch_ground_GActuator" >
  <visual >
   <geometry >
    <cylinder  length="0.0385"  radius="0.0425" />
   </geometry>
   <material  name="FL_branch_ground_GActuator_Material" >
    <color  rgba="0.9691119426182628 0.7475000981902138 0.802280616086089 0.9" />
   </material>
  </visual>
  <inertial >
   <inertia  iyy="0.006709166666666667"  izz="0.010306250000000001"  ixz="0.0"  iyz="0.0"  ixx="0.006709166666666667"  ixy="0.0" />
   <mass  value="0.1" />
  </inertial>
 </link>
 <link  name="FL_branch_ground_GUnit" >
  <visual >
   <geometry >
    <cylinder  length="0.08"  radius="0.04" />
   </geometry>
   <material  name="FL_branch_ground_GUnit_Material" >
    <color  rgba="0.9691119426182628 0.7475000981902138 0.802280616086089 0.9" />
   </material>
  </visual>
  <inertial >
   <inertia  iyy="0.0016666666666666666"  izz="0.002"  ixz="0.0"  iyz="0.0"  ixx="0.0016666666666666666"  ixy="0.0" />
   <mass  value="0.1" />
  </inertial>
 </link>
 <joint  type="fixed"  name="FL_branch_ground_G_WeldUnit" >
  <parent  link="G" />
  <child  link="FL_branch_ground_GUnit" />
  <origin  xyz="-0.10455651297933616 0.0 -0.002428905253078108"  rpy="-1.5707963267948966 -0.019670880781618605 -3.141592653589793" />
 </joint>
 <joint  type="revolute"  name="FL_branch_j0" >
  <parent  link="L21614" />
  <child  link="L21613" />
  <origin  xyz="4.579669976578771e-16 0.0 0.12977972884138245"  rpy="0.0 -0.35447055439720576 0.0" />
  <axis  xyz="0 1 0" />
  <limit  effort="600.0"  lower="-3.141592653589793"  upper="3.141592653589793"  velocity="6.283185307179586" />
  <dynamics  friction="0"  damping="0.05" />
 </joint>
 <link  name="FL_branch_j0_L21614Unit" >
  <visual >
   <geometry >
    <cylinder  length="0.04"  radius="0.02" />
   </geometry>
   <material  name="FL_branch_j0_L21614Unit_Material" >
    <color  rgba="0.8865138098454768 0.9791489879898532 0.9405348755563504 0.9" />
   </material>
  </visual>
  <inertial >
   <inertia  iyy="0.0008333333333333333"  izz="0.001"  ixz="0.0"  iyz="0.0"  ixx="0.0008333333333333333"  ixy="0.0" />
   <mass  value="0.1" />
  </inertial>
 </link>
 <joint  type="fixed"  name="FL_branch_j0_L21614_WeldUnit" >
  <parent  link="L21614" />
  <child  link="FL_branch_j0_L21614Unit" />
  <origin  xyz="4.579669976578771e-16 0.0 0.12977972884138245"  rpy="1.5707963267948966 -0.35447055439720576 0.0" />
 </joint>
 <joint  type="revolute"  name="FL_branch_j1" >
  <parent  link="L21613" />
  <child  link="L21615" />
  <origin  xyz="0.0 0.0 0.12289979734042797"  rpy="0.0 -1.3613418486355982 0.0" />
  <axis  xyz="0 1 0" />
  <limit  effort="600.0"  lower="-3.141592653589793"  upper="3.141592653589793"  velocity="6.283185307179586" />
  <dynamics  friction="0"  damping="0.05" />
 </joint>
 <link  name="FL_branch_j1_L21613Unit" >
  <visual >
   <geometry >
    <cylinder  length="0.03999999910593033"  radius="0.019999999552965164" />
   </geometry>
   <material  name="FL_branch_j1_L21613Unit_Material" >
    <color  rgba="0.28210517399101764 0.698724604126502 0.6638692433356483 0.9" />
   </material>
  </visual>
  <inertial >
   <inertia  iyy="0.0008333333147068819"  izz="0.0009999999776482583"  ixz="0.0"  iyz="0.0"  ixx="0.0008333333147068819"  ixy="0.0" />
   <mass  value="0.1" />
  </inertial>
 </link>
 <joint  type="fixed"  name="FL_branch_j1_L21613_WeldUnit" >
  <parent  link="L21613" />
  <child  link="FL_branch_j1_L21613Unit" />
  <origin  xyz="0.0 0.0 0.12289979734042797"  rpy="1.5707963267948966 -1.3613418486355982 -1.1102230246251565e-16" />
 </joint>
 <joint  type="revolute"  name="FL_branch_j2" >
  <parent  link="L21615" />
  <child  link="L21616" />
  <origin  xyz="0.0 0.0 0.05810430708767882"  rpy="0.0 0.4455006844331666 0.0" />
  <axis  xyz="0 1 0" />
  <limit  effort="600.0"  lower="-3.141592653589793"  upper="3.141592653589793"  velocity="6.283185307179586" />
  <dynamics  friction="0"  damping="0.05" />
 </joint>
 <link  name="FL_branch_j2_L21615Unit" >
  <visual >
   <geometry >
    <cylinder  length="0.04"  radius="0.02" />
   </geometry>
   <material  name="FL_branch_j2_L21615Unit_Material" >
    <color  rgba="0.3867408324893238 0.6010126359204915 0.5540397028842515 0.9" />
   </material>
  </visual>
  <inertial >
   <inertia  iyy="0.0008333333333333333"  izz="0.001"  ixz="0.0"  iyz="0.0"  ixx="0.0008333333333333333"  ixy="0.0" />
   <mass  value="0.1" />
  </inertial>
 </link>
 <joint  type="fixed"  name="FL_branch_j2_L21615_WeldUnit" >
  <parent  link="L21615" />
  <child  link="FL_branch_j2_L21615Unit" />
  <origin  xyz="0.0 0.0 0.05810430708767882"  rpy="1.5707963267948963 0.4455006844331666 0.0" />
 </joint>
 <link  name="FL_branch_top_L21611Pseudo" >
  <visual >
   <geometry >
    <sphere  radius="0.02857142793280738" />
   </geometry>
   <material  name="FL_branch_top_L21611Pseudo_Material" >
    <color  rgba="0.5939270336084382 0.6126896595828943 0.2958272939731498 0.5" />
   </material>
  </visual>
  <inertial >
   <mass  value="0.05" />
   <inertia  iyy="1.632652988239212e-05"  izz="1.632652988239212e-05"  ixz="0.0"  iyz="0.0"  ixx="1.632652988239212e-05"  ixy="0.0" />
  </inertial>
 </link>
 <joint  type="revolute"  name="FL_branch_top_L21611_revolute" >
  <parent  link="L21611" />
  <child  link="FL_branch_top_L21611Pseudo" />
  <origin  xyz="-0.0001260237216967498 0.0 0.3485992150342088"  rpy="0.0 0.0 0.0" />
  <axis  xyz="0 1 0" />
  <limit  effort="600.0"  lower="-3.141592653589793"  upper="3.141592653589793"  velocity="6.283185307179586" />
  <dynamics  friction="0"  damping="0.05" />
 </joint>
 <joint  type="fixed"  name="FL_branch_top_L21611_Weld" >
  <parent  link="L21616" />
  <child  link="FL_branch_top_L21616Pseudo" />
  <origin  xyz="0.0 0.0 0.19330986291309976"  rpy="0.0 0.72704206221972 0.0" />
 </joint>
 <link  name="FL_branch_top_L21616Pseudo" >
  <visual >
   <geometry >
    <sphere  radius="0.028571428571428574" />
   </geometry>
   <material  name="FL_branch_top_L21616Pseudo_Material" >
    <color  rgba="0.6536178921448756 0.33449775732404274 0.45724544805313605 0.5" />
   </material>
  </visual>
  <inertial >
   <mass  value="0.05" />
   <inertia  iyy="1.6326530612244903e-05"  izz="1.6326530612244903e-05"  ixz="0.0"  iyz="0.0"  ixx="1.6326530612244903e-05"  ixy="0.0" />
  </inertial>
 </link>
 <link  name="FL_branch_bot_L21612Pseudo" >
  <visual >
   <geometry >
    <sphere  radius="0.02857142793280738" />
   </geometry>
   <material  name="FL_branch_bot_L21612Pseudo_Material" >
    <color  rgba="0.03507239608413104 0.4595935723768264 0.9333413070384142 0.5" />
   </material>
  </visual>
  <inertial >
   <mass  value="0.05" />
   <inertia  iyy="1.632652988239212e-05"  izz="1.632652988239212e-05"  ixz="0.0"  iyz="0.0"  ixx="1.632652988239212e-05"  ixy="0.0" />
  </inertial>
 </link>
 <joint  type="revolute"  name="FL_branch_bot_L21612_revolute" >
  <parent  link="L21612" />
  <child  link="FL_branch_bot_L21612Pseudo" />
  <origin  xyz="0.00018447863724058156 0.0 0.3348635392173851"  rpy="3.141592653589793 0.5235987755982991 3.141592653589793" />
  <axis  xyz="0 1 0" />
  <limit  effort="600.0"  lower="-3.141592653589793"  upper="3.141592653589793"  velocity="6.283185307179586" />
  <dynamics  friction="0"  damping="0.05" />
 </joint>
 <joint  type="fixed"  name="FL_branch_bot_L21612_Weld" >
  <parent  link="L21613" />
  <child  link="FL_branch_bot_L21613Pseudo" />
  <origin  xyz="0.0005924326299545091 0.0 0.696184761774751"  rpy="3.141592653589793 -0.3347996736155874 3.141592653589793" />
 </joint>
 <link  name="FL_branch_bot_L21613Pseudo" >
  <visual >
   <geometry >
    <sphere  radius="0.02857142793280738" />
   </geometry>
   <material  name="FL_branch_bot_L21613Pseudo_Material" >
    <color  rgba="0.28210517399101764 0.698724604126502 0.6638692433356483 0.5" />
   </material>
  </visual>
  <inertial >
   <mass  value="0.05" />
   <inertia  iyy="1.632652988239212e-05"  izz="1.632652988239212e-05"  ixz="0.0"  iyz="0.0"  ixx="1.632652988239212e-05"  ixy="0.0" />
  </inertial>
 </link>
</robot>
