<?xml version="1.0"?>
<robot  name="Robot" >
 <link  name="L3" >
  <visual >
   <origin  rpy="0.0 0.09181105459193106 0.0"  xyz="-0.004108099428788401 0.0 0.05993599385656579" />
   <geometry >
    <box  size="0.03350000083446503 0.03350000083446503 0.05611614631658583" />
   </geometry>
   <material  name="L3_Material" >
    <color  rgba="0.1568627450980392 0.42745098039215684 0.8 1.0" />
   </material>
  </visual>
  <collision  name="L3_0_Collision" >
   <origin  rpy="0.0 0.09181105459193106 0.0"  xyz="-0.004108099428788401 0.0 0.05993599385656579" />
   <geometry >
    <box  size="0.03350000083446503 0.03350000083446503 0.05611614631658583" />
   </geometry>
  </collision>
  <collision  name="L3_0_Collision" >
   <origin  rpy="0.0 0.09181105459193106 0.0"  xyz="-0.004108099428788401 0.0 0.05993599385656579" />
   <geometry >
    <box  size="0.03350000083446503 0.03350000083446503 0.05611614631658583" />
   </geometry>
  </collision>
  <visual >
   <origin  rpy="3.141592653589793 0.49235980655335787 3.141592653589793"  xyz="-0.004108099428788413 0.0 0.00765831866618727" />
   <geometry >
    <box  size="0.03350000083446503 0.03350000083446503 0.01738117668165007" />
   </geometry>
   <material  name="L3_Material" >
    <color  rgba="0.1568627450980392 0.42745098039215684 0.8 1.0" />
   </material>
  </visual>
  <collision  name="L3_1_Collision" >
   <origin  rpy="3.141592653589793 0.49235980655335787 3.141592653589793"  xyz="-0.004108099428788413 0.0 0.00765831866618727" />
   <geometry >
    <box  size="0.03350000083446503 0.03350000083446503 0.01738117668165007" />
   </geometry>
  </collision>
  <collision  name="L3_1_Collision" >
   <origin  rpy="3.141592653589793 0.49235980655335787 3.141592653589793"  xyz="-0.004108099428788413 0.0 0.00765831866618727" />
   <geometry >
    <box  size="0.03350000083446503 0.03350000083446503 0.01738117668165007" />
   </geometry>
  </collision>
  <visual >
   <origin  rpy="0.0 0.0 0.0"  xyz="1.1860980540876177e-17 0.0 0.05227767519037852" />
   <geometry >
    <box  size="0.03350000083446503 0.03350000083446503 0.07105534954629202" />
   </geometry>
   <material  name="L3_Material" >
    <color  rgba="0.1568627450980392 0.42745098039215684 0.8 1.0" />
   </material>
  </visual>
  <collision  name="L3_2_Collision" >
   <origin  rpy="0.0 0.0 0.0"  xyz="1.1860980540876177e-17 0.0 0.05227767519037852" />
   <geometry >
    <box  size="0.03350000083446503 0.03350000083446503 0.07105534954629202" />
   </geometry>
  </collision>
  <collision  name="L3_2_Collision" >
   <origin  rpy="0.0 0.0 0.0"  xyz="1.1860980540876177e-17 0.0 0.05227767519037852" />
   <geometry >
    <box  size="0.03350000083446503 0.03350000083446503 0.07105534954629202" />
   </geometry>
  </collision>
  <inertial >
   <origin  rpy="0.0 0.0 0.0"  xyz="-0.00274 0.0 0.03996" />
   <mass  value="0.09685269889407332" />
   <inertia  iyz="-2.4161305388705388e-22"  izz="6.166570747812177e-05"  ixz="0.00018308466180655771"  ixy="2.695850918604945e-22"  ixx="0.0008365423144498885"  iyy="0.0008800925308032057" />
  </inertial>
 </link>
 <link  name="G" >
  <visual >
   <origin  rpy="0.0 0.0 0.0"  xyz="0.0 0.0 0.0" />
   <geometry >
    <box  size="0.067 0.067 0.067" />
   </geometry>
   <material  name="G_Material" >
    <color  rgba="0.37254901960784315 0.5019607843137255 0.8352941176470589 1.0" />
   </material>
  </visual>
  <collision  name="G_Collision" >
   <origin  rpy="0.0 0.0 0.0"  xyz="0.0 0.0 0.0" />
   <geometry >
    <box  size="0.067 0.067 0.067" />
   </geometry>
  </collision>
  <inertial >
   <origin  rpy="0.0 0.0 0.0"  xyz="0.0 0.0 0.0" />
   <mass  value="0.04903493747122909" />
   <inertia  iyz="0.0"  izz="3.66863057180579e-05"  ixz="0.0"  ixy="0.0"  ixx="3.66863057180579e-05"  iyy="3.66863057180579e-05" />
  </inertial>
 </link>
 <link  name="L4" >
  <visual >
   <origin  rpy="0.0 0.0 0.0"  xyz="-1.3877787807814457e-17 0.0 0.15066903897197254" />
   <geometry >
    <box  size="0.03350000083446503 0.03350000083446503 0.26783807710948004" />
   </geometry>
   <material  name="L4_Material" >
    <color  rgba="0.5176470588235295 0.5843137254901961 0.8705882352941177 1.0" />
   </material>
  </visual>
  <collision  name="L4_0_Collision" >
   <origin  rpy="0.0 0.0 0.0"  xyz="-1.3877787807814457e-17 0.0 0.15066903897197254" />
   <geometry >
    <box  size="0.03350000083446503 0.03350000083446503 0.26783807710948004" />
   </geometry>
  </collision>
  <collision  name="L4_0_Collision" >
   <origin  rpy="0.0 0.0 0.0"  xyz="-1.3877787807814457e-17 0.0 0.15066903897197254" />
   <geometry >
    <box  size="0.03350000083446503 0.03350000083446503 0.26783807710948004" />
   </geometry>
  </collision>
  <visual >
   <origin  rpy="3.141592653589793 0.04302627908889378 3.141592653589793"  xyz="0.0041903171318351945 0.0 0.20400846656394397" />
   <geometry >
    <box  size="0.03350000083446503 0.03350000083446503 0.16133954349930096" />
   </geometry>
   <material  name="L4_Material" >
    <color  rgba="0.5176470588235295 0.5843137254901961 0.8705882352941177 1.0" />
   </material>
  </visual>
  <collision  name="L4_1_Collision" >
   <origin  rpy="3.141592653589793 0.04302627908889378 3.141592653589793"  xyz="0.0041903171318351945 0.0 0.20400846656394397" />
   <geometry >
    <box  size="0.03350000083446503 0.03350000083446503 0.16133954349930096" />
   </geometry>
  </collision>
  <collision  name="L4_1_Collision" >
   <origin  rpy="3.141592653589793 0.04302627908889378 3.141592653589793"  xyz="0.0041903171318351945 0.0 0.20400846656394397" />
   <geometry >
    <box  size="0.03350000083446503 0.03350000083446503 0.16133954349930096" />
   </geometry>
  </collision>
  <visual >
   <origin  rpy="0.0 0.07839845297202364 0.0"  xyz="0.004190317131835208 0.0 0.05333942759197144" />
   <geometry >
    <box  size="0.03350000083446503 0.03350000083446503 0.07350753709636516" />
   </geometry>
   <material  name="L4_Material" >
    <color  rgba="0.5176470588235295 0.5843137254901961 0.8705882352941177 1.0" />
   </material>
  </visual>
  <collision  name="L4_2_Collision" >
   <origin  rpy="0.0 0.07839845297202364 0.0"  xyz="0.004190317131835208 0.0 0.05333942759197144" />
   <geometry >
    <box  size="0.03350000083446503 0.03350000083446503 0.07350753709636516" />
   </geometry>
  </collision>
  <collision  name="L4_2_Collision" >
   <origin  rpy="0.0 0.07839845297202364 0.0"  xyz="0.004190317131835208 0.0 0.05333942759197144" />
   <geometry >
    <box  size="0.03350000083446503 0.03350000083446503 0.07350753709636516" />
   </geometry>
  </collision>
  <inertial >
   <origin  rpy="0.0 0.0 0.0"  xyz="0.00279 0.0 0.13601" />
   <mass  value="0.27559273891349373" />
   <inertia  iyz="-1.787784584408132e-21"  izz="0.00010556823177187275"  ixz="0.000895771586742282"  ixy="6.490733712540504e-22"  ixx="0.04267591652550551"  iyy="0.04272993742950175" />
  </inertial>
 </link>
 <link  name="EE" >
  <visual >
   <origin  rpy="0.0 0.0 0.0"  xyz="0.0 0.0 0.0" />
   <geometry >
    <sphere  radius="0.002142857142857143" />
   </geometry>
   <material  name="EE_Material" >
    <color  rgba="0.6431372549019608 0.6666666666666666 0.9058823529411765 1.0" />
   </material>
  </visual>
  <collision  name="EE_Collision" >
   <origin  rpy="0.0 0.0 0.0"  xyz="0.0 0.0 0.0" />
   <geometry >
    <sphere  radius="0.002142857142857143" />
   </geometry>
  </collision>
  <inertial >
   <origin  rpy="0.0 0.0 0.0"  xyz="0.0 0.0 0.0" />
   <mass  value="2.982076683750377e-05" />
   <inertia  iyz="0.0"  izz="5.477283704847632e-11"  ixz="0.0"  ixy="0.0"  ixx="5.477283704847632e-11"  iyy="5.477283704847632e-11" />
  </inertial>
 </link>
 <link  name="L8" >
  <visual >
   <origin  rpy="0.0 0.0 0.0"  xyz="-0.0 0.0 0.06016" />
   <geometry >
    <box  size="0.0335 0.0335 0.08682350477047437" />
   </geometry>
   <material  name="L8_Material" >
    <color  rgba="0.01568627450980392 0.5058823529411764 0.29411764705882354 1.0" />
   </material>
  </visual>
  <collision  name="L8_Collision" >
   <origin  rpy="0.0 0.0 0.0"  xyz="-0.0 0.0 0.06016" />
   <geometry >
    <box  size="0.0335 0.0335 0.08682350477047437" />
   </geometry>
  </collision>
  <inertial >
   <origin  rpy="0.0 0.0 0.0"  xyz="-0.0 0.0 0.06016" />
   <mass  value="0.07049810895200362" />
   <inertia  iyz="0.0"  izz="1.3186083795231012e-05"  ixz="0.0"  ixy="0.0"  ixx="5.087948971490957e-05"  iyy="5.087948971490957e-05" />
  </inertial>
 </link>
 <link  name="L5" >
  <visual >
   <origin  rpy="0.0 0.15776220589854817 0.0"  xyz="0.008088247928544748 0.0 0.1336198697017476" />
   <geometry >
    <box  size="0.03350000083446503 0.03350000083446503 0.06946378375115986" />
   </geometry>
   <material  name="L5_Material" >
    <color  rgba="0.0 0.6627450980392157 0.3607843137254902 1.0" />
   </material>
  </visual>
  <collision  name="L5_0_Collision" >
   <origin  rpy="0.0 0.15776220589854817 0.0"  xyz="0.008088247928544748 0.0 0.1336198697017476" />
   <geometry >
    <box  size="0.03350000083446503 0.03350000083446503 0.06946378375115986" />
   </geometry>
  </collision>
  <collision  name="L5_0_Collision" >
   <origin  rpy="0.0 0.15776220589854817 0.0"  xyz="0.008088247928544748 0.0 0.1336198697017476" />
   <geometry >
    <box  size="0.03350000083446503 0.03350000083446503 0.06946378375115986" />
   </geometry>
  </collision>
  <visual >
   <origin  rpy="0.0 0.0 0.0"  xyz="-1.3877787807814457e-17 0.0 0.041388656954714" />
   <geometry >
    <box  size="0.03350000083446503 0.03350000083446503 0.04927731307496297" />
   </geometry>
   <material  name="L5_Material" >
    <color  rgba="0.0 0.6627450980392157 0.3607843137254902 1.0" />
   </material>
  </visual>
  <collision  name="L5_1_Collision" >
   <origin  rpy="0.0 0.0 0.0"  xyz="-1.3877787807814457e-17 0.0 0.041388656954714" />
   <geometry >
    <box  size="0.03350000083446503 0.03350000083446503 0.04927731307496297" />
   </geometry>
  </collision>
  <collision  name="L5_1_Collision" >
   <origin  rpy="0.0 0.0 0.0"  xyz="-1.3877787807814457e-17 0.0 0.041388656954714" />
   <geometry >
    <box  size="0.03350000083446503 0.03350000083446503 0.04927731307496297" />
   </geometry>
  </collision>
  <visual >
   <origin  rpy="-3.141592653589793 -0.08747156941082657 3.141592653589793"  xyz="0.008088247928544762 0.0 0.09223121274703361" />
   <geometry >
    <box  size="0.03350000083446503 0.03350000083446503 0.1516703678462954" />
   </geometry>
   <material  name="L5_Material" >
    <color  rgba="0.0 0.6627450980392157 0.3607843137254902 1.0" />
   </material>
  </visual>
  <collision  name="L5_2_Collision" >
   <origin  rpy="-3.141592653589793 -0.08747156941082657 3.141592653589793"  xyz="0.008088247928544762 0.0 0.09223121274703361" />
   <geometry >
    <box  size="0.03350000083446503 0.03350000083446503 0.1516703678462954" />
   </geometry>
  </collision>
  <collision  name="L5_2_Collision" >
   <origin  rpy="-3.141592653589793 -0.08747156941082657 3.141592653589793"  xyz="0.008088247928544762 0.0 0.09223121274703361" />
   <geometry >
    <box  size="0.03350000083446503 0.03350000083446503 0.1516703678462954" />
   </geometry>
  </collision>
  <inertial >
   <origin  rpy="0.0 0.0 0.0"  xyz="0.00539 0.0 0.08908" />
   <mass  value="0.16698601834510818" />
   <inertia  iyz="5.82800099357015e-21"  izz="0.0005750110691996042"  ixz="-0.001546053058079428"  ixy="-7.644705710738078e-21"  ixx="0.008306275939171324"  iyy="0.008850053663633619" />
  </inertial>
 </link>
 <link  name="L6" >
  <visual >
   <origin  rpy="0.0 0.0 0.0"  xyz="0.0 0.0 0.09894" />
   <geometry >
    <box  size="0.0335 0.0335 0.16437820472978457" />
   </geometry>
   <material  name="L6_Material" >
    <color  rgba="0.0 0.8274509803921568 0.4196078431372549 1.0" />
   </material>
  </visual>
  <collision  name="L6_Collision" >
   <origin  rpy="0.0 0.0 0.0"  xyz="0.0 0.0 0.09894" />
   <geometry >
    <box  size="0.0335 0.0335 0.16437820472978457" />
   </geometry>
  </collision>
  <inertial >
   <origin  rpy="0.0 0.0 0.0"  xyz="0.0 0.0 0.09894" />
   <mass  value="0.1334702234954687" />
   <inertia  iyz="0.0"  izz="2.496449305296496e-05"  ixz="0.0"  ixy="0.0"  ixx="0.00031301485964775074"  iyy="0.00031301485964775074" />
  </inertial>
 </link>
 <link  name="L7" >
  <visual >
   <origin  rpy="0.0 0.0 0.0"  xyz="0.0 0.0 0.06513" />
   <geometry >
    <box  size="0.0335 0.0335 0.09676022409008955" />
   </geometry>
   <material  name="L7_Material" >
    <color  rgba="0.0 1.0 0.4666666666666667 1.0" />
   </material>
  </visual>
  <collision  name="L7_Collision" >
   <origin  rpy="0.0 0.0 0.0"  xyz="0.0 0.0 0.06513" />
   <geometry >
    <box  size="0.0335 0.0335 0.09676022409008955" />
   </geometry>
  </collision>
  <inertial >
   <origin  rpy="0.0 0.0 0.0"  xyz="0.0 0.0 0.06513" />
   <mass  value="0.07856643011770174" />
   <inertia  iyz="0.0"  izz="1.4695196033265132e-05"  ixz="0.0"  ixy="0.0"  ixx="6.864604972717903e-05"  iyy="6.864604972717903e-05" />
  </inertial>
 </link>
 <joint  name="Main_ground"  type="revolute" >
  <parent  link="G" />
  <child  link="L3" />
  <origin  rpy="3.141592653589793 0.2910198718830985 3.141592653589793"  xyz="0.0 0.0 0.0" />
  <axis  xyz="0 1 0" />
  <limit  velocity="23.99988291783386"  effort="10.2"  lower="-3.141592653589793"  upper="3.141592653589793" />
  <dynamics  friction="0"  damping="0.05" />
 </joint>
 <joint  name="Main_ground_G_WeldActuator"  type="fixed" >
  <parent  link="G" />
  <child  link="Main_ground_GActuator" />
  <origin  rpy="-1.5707963267948972 0.29101987188309875 -3.141592653589793"  xyz="0.0 0.03675000041723252 0.0" />
 </joint>
 <link  name="Main_ground_GActuator" >
  <visual >
   <geometry >
    <cylinder  length="0.04"  radius="0.048" />
   </geometry>
   <material  name="Main_ground_GActuator_Material" >
    <color  rgba="0.37254901960784315 0.5019607843137255 0.8352941176470589 0.9" />
   </material>
  </visual>
  <inertial >
   <inertia  iyz="0.0"  izz="0.01056"  ixz="0.0"  ixy="0.0"  ixx="0.0067466666666666664"  iyy="0.0067466666666666664" />
   <mass  value="0.44" />
  </inertial>
 </link>
 <link  name="Main_ground_GUnit" >
  <visual >
   <geometry >
    <cylinder  length="0.03350000083446503"  radius="0.016750000417232513" />
   </geometry>
   <material  name="Main_ground_GUnit_Material" >
    <color  rgba="0.37254901960784315 0.5019607843137255 0.8352941176470589 0.9" />
   </material>
  </visual>
  <inertial >
   <inertia  iyz="0.0"  izz="0.0008375000208616257"  ixz="0.0"  ixy="0.0"  ixx="0.0006979166840513548"  iyy="0.0006979166840513548" />
   <mass  value="0.1" />
  </inertial>
 </link>
 <joint  name="Main_ground_G_WeldUnit"  type="fixed" >
  <parent  link="G" />
  <child  link="Main_ground_GUnit" />
  <origin  rpy="-1.5707963267948972 0.29101987188309875 -3.141592653589793"  xyz="0.0 0.0 0.0" />
 </joint>
 <joint  name="Main_knee"  type="revolute" >
  <parent  link="L3" />
  <child  link="L4" />
  <origin  rpy="0.0 0.39074102059579907 0.0"  xyz="2.3721961081752355e-17 0.0 0.10455535038075704" />
  <axis  xyz="0 1 0" />
  <limit  velocity="6.283185307179586"  effort="600.0"  lower="-3.141592653589793"  upper="3.141592653589793" />
  <dynamics  friction="0"  damping="0.05" />
 </joint>
 <link  name="Main_knee_L3Unit" >
  <visual >
   <geometry >
    <cylinder  length="0.03"  radius="0.016" />
   </geometry>
   <material  name="Main_knee_L3Unit_Material" >
    <color  rgba="0.1568627450980392 0.42745098039215684 0.8 0.9" />
   </material>
  </visual>
  <inertial >
   <inertia  iyz="0.0"  izz="0.0008"  ixz="0.0"  ixy="0.0"  ixx="0.00065"  iyy="0.00065" />
   <mass  value="0.1" />
  </inertial>
 </link>
 <joint  name="Main_knee_L3_WeldUnit"  type="fixed" >
  <parent  link="L3" />
  <child  link="Main_knee_L3Unit" />
  <origin  rpy="1.5707963267948966 0.39074102059579907 -1.1102230246251565e-16"  xyz="2.3721961081752355e-17 0.0 0.10455535038075704" />
 </joint>
 <joint  name="Main_ee"  type="fixed" >
  <parent  link="L4" />
  <child  link="EE" />
  <origin  rpy="3.141592653589793 0.0997211487127001 3.141592653589793"  xyz="-2.7755575615628914e-17 0.0 0.30133807794394507" />
 </joint>
 <link  name="Main_ee_L4Unit" >
  <visual >
   <geometry >
    <cylinder  length="0.03"  radius="0.016" />
   </geometry>
   <material  name="Main_ee_L4Unit_Material" >
    <color  rgba="0.5176470588235295 0.5843137254901961 0.8705882352941177 0.9" />
   </material>
  </visual>
  <inertial >
   <inertia  iyz="0.0"  izz="0.0008"  ixz="0.0"  ixy="0.0"  ixx="0.00065"  iyy="0.00065" />
   <mass  value="0.1" />
  </inertial>
 </link>
 <joint  name="Main_ee_L4_WeldUnit"  type="fixed" >
  <parent  link="L4" />
  <child  link="Main_ee_L4Unit" />
  <origin  rpy="-1.570796326794897 0.09972114871270032 3.1415926535897927"  xyz="-2.7755575615628914e-17 0.0 0.30133807794394507" />
 </joint>
 <link  name="Main_connection_1_L3Pseudo" >
  <visual >
   <geometry >
    <sphere  radius="0.02392857202461788" />
   </geometry>
   <material  name="Main_connection_1_L3Pseudo_Material" >
    <color  rgba="0.1568627450980392 0.42745098039215684 0.8 0.5" />
   </material>
  </visual>
  <inertial >
   <mass  value="0.05" />
   <inertia  iyz="0.0"  izz="1.145153118274651e-05"  ixz="0.0"  ixy="0.0"  ixx="1.145153118274651e-05"  iyy="1.145153118274651e-05" />
  </inertial>
 </link>
 <joint  name="Main_connection_1_L3_revolute"  type="revolute" >
  <parent  link="L3" />
  <child  link="Main_connection_1_L3Pseudo" />
  <origin  rpy="0.0 0.0 0.0"  xyz="-0.008216198857576826 0.0 0.01531663733237454" />
  <axis  xyz="0 1 0" />
  <limit  velocity="6.283185307179586"  effort="600.0"  lower="-3.141592653589793"  upper="3.141592653589793" />
  <dynamics  friction="0"  damping="0.05" />
 </joint>
 <joint  name="Main_connection_1_L3_Weld"  type="fixed" >
  <parent  link="L8" />
  <child  link="Main_connection_1_L8Pseudo" />
  <origin  rpy="3.141592653589793 0.7793676453643523 3.141592653589793"  xyz="-3.8163916471489756e-17 0.0 0.12032350477047436" />
 </joint>
 <link  name="Main_connection_1_L8Pseudo" >
  <visual >
   <geometry >
    <sphere  radius="0.02392857142857143" />
   </geometry>
   <material  name="Main_connection_1_L8Pseudo_Material" >
    <color  rgba="0.01568627450980392 0.5058823529411764 0.29411764705882354 0.5" />
   </material>
  </visual>
  <inertial >
   <mass  value="0.05" />
   <inertia  iyz="0.0"  izz="1.1451530612244902e-05"  ixz="0.0"  ixy="0.0"  ixx="1.1451530612244902e-05"  iyy="1.1451530612244902e-05" />
  </inertial>
 </link>
 <joint  name="branch_0"  type="revolute" >
  <parent  link="L5" />
  <child  link="L8" />
  <origin  rpy="3.141592653589793 -1.2122419352302822 3.141592653589793"  xyz="-2.7755575615628914e-17 0.0 0.082777313909428" />
  <axis  xyz="0 1 0" />
  <limit  velocity="6.283185307179586"  effort="600.0"  lower="-3.141592653589793"  upper="3.141592653589793" />
  <dynamics  friction="0"  damping="0.05" />
 </joint>
 <link  name="branch_0_L5Unit" >
  <visual >
   <geometry >
    <cylinder  length="0.03"  radius="0.016" />
   </geometry>
   <material  name="branch_0_L5Unit_Material" >
    <color  rgba="0.0 0.6627450980392157 0.3607843137254902 0.9" />
   </material>
  </visual>
  <inertial >
   <inertia  iyz="0.0"  izz="0.0008"  ixz="0.0"  ixy="0.0"  ixx="0.00065"  iyy="0.00065" />
   <mass  value="0.1" />
  </inertial>
 </link>
 <joint  name="branch_0_L5_WeldUnit"  type="fixed" >
  <parent  link="L5" />
  <child  link="branch_0_L5Unit" />
  <origin  rpy="-1.570796326794896 -1.2122419352302822 3.1415926535897922"  xyz="-2.7755575615628914e-17 0.0 0.082777313909428" />
 </joint>
 <link  name="Main_connection_2_L5Pseudo" >
  <visual >
   <geometry >
    <sphere  radius="0.02392857202461788" />
   </geometry>
   <material  name="Main_connection_2_L5Pseudo_Material" >
    <color  rgba="0.0 0.6627450980392157 0.3607843137254902 0.5" />
   </material>
  </visual>
  <inertial >
   <mass  value="0.05" />
   <inertia  iyz="0.0"  izz="1.145153118274651e-05"  ixz="0.0"  ixy="0.0"  ixx="1.145153118274651e-05"  iyy="1.145153118274651e-05" />
  </inertial>
 </link>
 <joint  name="Main_connection_2_L5_revolute"  type="revolute" >
  <parent  link="L5" />
  <child  link="Main_connection_2_L5Pseudo" />
  <origin  rpy="3.141592653589793 -1.2122419352302822 3.141592653589793"  xyz="0.016176495857089523 0.0 0.18446242549406722" />
  <axis  xyz="0 1 0" />
  <limit  velocity="6.283185307179586"  effort="600.0"  lower="-3.141592653589793"  upper="3.141592653589793" />
  <dynamics  friction="0"  damping="0.05" />
 </joint>
 <joint  name="Main_connection_2_L5_Weld"  type="fixed" >
  <parent  link="L4" />
  <child  link="Main_connection_2_L4Pseudo" />
  <origin  rpy="3.141592653589793 -0.3886266247685537 3.141592653589793"  xyz="0.008380634263670333 0.0 0.10667885518394299" />
 </joint>
 <link  name="Main_connection_2_L4Pseudo" >
  <visual >
   <geometry >
    <sphere  radius="0.02392857202461788" />
   </geometry>
   <material  name="Main_connection_2_L4Pseudo_Material" >
    <color  rgba="0.5176470588235295 0.5843137254901961 0.8705882352941177 0.5" />
   </material>
  </visual>
  <inertial >
   <mass  value="0.05" />
   <inertia  iyz="0.0"  izz="1.145153118274651e-05"  ixz="0.0"  ixy="0.0"  ixx="1.145153118274651e-05"  iyy="1.145153118274651e-05" />
  </inertial>
 </link>
 <joint  name="branch_1"  type="revolute" >
  <parent  link="L6" />
  <child  link="L5" />
  <origin  rpy="0.0 0.9252881250839118 0.0"  xyz="2.7755575615628914e-17 0.0 0.1978782047297846" />
  <axis  xyz="0 1 0" />
  <limit  velocity="6.283185307179586"  effort="600.0"  lower="-3.141592653589793"  upper="3.141592653589793" />
  <dynamics  friction="0"  damping="0.05" />
 </joint>
 <link  name="branch_1_L6Unit" >
  <visual >
   <geometry >
    <cylinder  length="0.03"  radius="0.016" />
   </geometry>
   <material  name="branch_1_L6Unit_Material" >
    <color  rgba="0.0 0.8274509803921568 0.4196078431372549 0.9" />
   </material>
  </visual>
  <inertial >
   <inertia  iyz="0.0"  izz="0.0008"  ixz="0.0"  ixy="0.0"  ixx="0.00065"  iyy="0.00065" />
   <mass  value="0.1" />
  </inertial>
 </link>
 <joint  name="branch_1_L6_WeldUnit"  type="fixed" >
  <parent  link="L6" />
  <child  link="branch_1_L6Unit" />
  <origin  rpy="1.5707963267948966 0.9252881250839118 1.1102230246251565e-16"  xyz="2.7755575615628914e-17 0.0 0.1978782047297846" />
 </joint>
 <joint  name="Ground_connection"  type="revolute" >
  <parent  link="G" />
  <child  link="L7" />
  <origin  rpy="3.141592653589793 -0.8557299655225146 3.141592653589793"  xyz="-0.1979280269259157 0.0 0.013357911869671868" />
  <axis  xyz="0 1 0" />
  <limit  velocity="23.99988291783386"  effort="10.2"  lower="-3.141592653589793"  upper="3.141592653589793" />
  <dynamics  friction="0"  damping="0.05" />
 </joint>
 <joint  name="Ground_connection_G_WeldActuator"  type="fixed" >
  <parent  link="G" />
  <child  link="Ground_connection_GActuator" />
  <origin  rpy="-1.5707963267948963 -0.8557299655225148 -3.141592653589793"  xyz="-0.1979280269259157 0.036750000000000005 0.013357911869671868" />
 </joint>
 <link  name="Ground_connection_GActuator" >
  <visual >
   <geometry >
    <cylinder  length="0.04"  radius="0.048" />
   </geometry>
   <material  name="Ground_connection_GActuator_Material" >
    <color  rgba="0.37254901960784315 0.5019607843137255 0.8352941176470589 0.9" />
   </material>
  </visual>
  <inertial >
   <inertia  iyz="0.0"  izz="0.01056"  ixz="0.0"  ixy="0.0"  ixx="0.0067466666666666664"  iyy="0.0067466666666666664" />
   <mass  value="0.44" />
  </inertial>
 </link>
 <link  name="Ground_connection_GUnit" >
  <visual >
   <geometry >
    <cylinder  length="0.0335"  radius="0.01675" />
   </geometry>
   <material  name="Ground_connection_GUnit_Material" >
    <color  rgba="0.37254901960784315 0.5019607843137255 0.8352941176470589 0.9" />
   </material>
  </visual>
  <inertial >
   <inertia  iyz="0.0"  izz="0.0008375000000000001"  ixz="0.0"  ixy="0.0"  ixx="0.0006979166666666668"  iyy="0.0006979166666666668" />
   <mass  value="0.1" />
  </inertial>
 </link>
 <joint  name="Ground_connection_G_WeldUnit"  type="fixed" >
  <parent  link="G" />
  <child  link="Ground_connection_GUnit" />
  <origin  rpy="-1.5707963267948963 -0.8557299655225148 -3.141592653589793"  xyz="-0.1979280269259157 0.0 0.013357911869671868" />
 </joint>
 <joint  name="branch_2"  type="revolute" >
  <parent  link="L7" />
  <child  link="L6" />
  <origin  rpy="3.141592653589793 -0.6366804012343384 3.141592653589793"  xyz="2.7755575615628914e-17 0.0 0.13026022409008958" />
  <axis  xyz="0 1 0" />
  <limit  velocity="6.283185307179586"  effort="600.0"  lower="-3.141592653589793"  upper="3.141592653589793" />
  <dynamics  friction="0"  damping="0.05" />
 </joint>
 <link  name="branch_2_L7Unit" >
  <visual >
   <geometry >
    <cylinder  length="0.03"  radius="0.016" />
   </geometry>
   <material  name="branch_2_L7Unit_Material" >
    <color  rgba="0.0 1.0 0.4666666666666667 0.9" />
   </material>
  </visual>
  <inertial >
   <inertia  iyz="0.0"  izz="0.0008"  ixz="0.0"  ixy="0.0"  ixx="0.00065"  iyy="0.00065" />
   <mass  value="0.1" />
  </inertial>
 </link>
 <joint  name="branch_2_L7_WeldUnit"  type="fixed" >
  <parent  link="L7" />
  <child  link="branch_2_L7Unit" />
  <origin  rpy="-1.5707963267948966 -0.6366804012343384 -3.141592653589793"  xyz="2.7755575615628914e-17 0.0 0.13026022409008958" />
 </joint>
</robot>
