<?xml version="1.0"?>
<robot  name="Robot" >
 <link  name="G" >
  <visual >
   <origin  rpy="0.0 0.0 0.0"  xyz="0.0 0.0 0.0" />
   <geometry >
    <box  size="0.067 0.067 0.067" />
   </geometry>
   <material  name="G_Material" >
    <color  rgba="0.1568627450980392 0.42745098039215684 0.8 1.0" />
   </material>
  </visual>
  <collision  name="G_Collision" >
   <origin  rpy="0.0 0.0 0.0"  xyz="0.0 0.0 0.0" />
   <geometry >
    <box  size="0.067 0.067 0.067" />
   </geometry>
  </collision>
  <inertial >
   <origin  rpy="0.0 0.0 0.0"  xyz="0.0 0.0 0.0" />
   <mass  value="0.04903493747122909" />
   <inertia  ixy="0.0"  ixz="0.0"  iyz="0.0"  iyy="3.66863057180579e-05"  ixx="3.66863057180579e-05"  izz="3.66863057180579e-05" />
  </inertial>
 </link>
 <link  name="L6" >
  <visual >
   <origin  rpy="0.0 0.0 0.0"  xyz="2.2551405187698492e-17 0.0 0.08532877591996735" />
   <geometry >
    <box  size="0.03350000083446503 0.03350000083446503 0.13715755100546967" />
   </geometry>
   <material  name="L6_Material" >
    <color  rgba="0.37254901960784315 0.5019607843137255 0.8352941176470589 1.0" />
   </material>
  </visual>
  <collision  name="L6_0_Collision" >
   <origin  rpy="0.0 0.0 0.0"  xyz="2.2551405187698492e-17 0.0 0.08532877591996735" />
   <geometry >
    <box  size="0.03350000083446503 0.03350000083446503 0.13715755100546967" />
   </geometry>
  </collision>
  <collision  name="L6_0_Collision" >
   <origin  rpy="0.0 0.0 0.0"  xyz="2.2551405187698492e-17 0.0 0.08532877591996735" />
   <geometry >
    <box  size="0.03350000083446503 0.03350000083446503 0.13715755100546967" />
   </geometry>
  </collision>
  <visual >
   <origin  rpy="-3.141592653589793 -0.28637240030263866 3.141592653589793"  xyz="-0.0127139876120751 0.0 0.12748119122443122" />
   <geometry >
    <box  size="0.03350000083446503 0.03350000083446503 0.05651874381352481" />
   </geometry>
   <material  name="L6_Material" >
    <color  rgba="0.37254901960784315 0.5019607843137255 0.8352941176470589 1.0" />
   </material>
  </visual>
  <collision  name="L6_1_Collision" >
   <origin  rpy="-3.141592653589793 -0.28637240030263866 3.141592653589793"  xyz="-0.0127139876120751 0.0 0.12748119122443122" />
   <geometry >
    <box  size="0.03350000083446503 0.03350000083446503 0.05651874381352481" />
   </geometry>
  </collision>
  <collision  name="L6_1_Collision" >
   <origin  rpy="-3.141592653589793 -0.28637240030263866 3.141592653589793"  xyz="-0.0127139876120751 0.0 0.12748119122443122" />
   <geometry >
    <box  size="0.03350000083446503 0.03350000083446503 0.05651874381352481" />
   </geometry>
  </collision>
  <visual >
   <origin  rpy="0.0 -0.29294185000394 0.0"  xyz="-0.012713987612075123 0.0 0.042152415304463876" />
   <geometry >
    <box  size="0.03350000083446503 0.03350000083446503 0.054556153907835636" />
   </geometry>
   <material  name="L6_Material" >
    <color  rgba="0.37254901960784315 0.5019607843137255 0.8352941176470589 1.0" />
   </material>
  </visual>
  <collision  name="L6_2_Collision" >
   <origin  rpy="0.0 -0.29294185000394 0.0"  xyz="-0.012713987612075123 0.0 0.042152415304463876" />
   <geometry >
    <box  size="0.03350000083446503 0.03350000083446503 0.054556153907835636" />
   </geometry>
  </collision>
  <collision  name="L6_2_Collision" >
   <origin  rpy="0.0 -0.29294185000394 0.0"  xyz="-0.012713987612075123 0.0 0.042152415304463876" />
   <geometry >
    <box  size="0.03350000083446503 0.03350000083446503 0.054556153907835636" />
   </geometry>
  </collision>
  <inertial >
   <origin  rpy="0.0 0.0 0.0"  xyz="-0.00848 0.0 0.08499" />
   <mass  value="0.19417013715180462" />
   <inertia  ixy="-1.7042205772311903e-21"  ixz="0.0010549703096108104"  iyz="6.19216315366613e-21"  iyy="0.006098382232245788"  ixx="0.00588651139708762"  izz="0.0002481887430372511" />
  </inertial>
 </link>
 <link  name="L7" >
  <visual >
   <origin  rpy="0.0 0.0 0.0"  xyz="4.85722573273506e-17 0.0 0.11696580696938742" />
   <geometry >
    <box  size="0.03350000083446503 0.03350000083446503 0.20043161310430982" />
   </geometry>
   <material  name="L7_Material" >
    <color  rgba="0.5176470588235295 0.5843137254901961 0.8705882352941177 1.0" />
   </material>
  </visual>
  <collision  name="L7_0_Collision" >
   <origin  rpy="0.0 0.0 0.0"  xyz="4.85722573273506e-17 0.0 0.11696580696938742" />
   <geometry >
    <box  size="0.03350000083446503 0.03350000083446503 0.20043161310430982" />
   </geometry>
  </collision>
  <collision  name="L7_0_Collision" >
   <origin  rpy="0.0 0.0 0.0"  xyz="4.85722573273506e-17 0.0 0.11696580696938742" />
   <geometry >
    <box  size="0.03350000083446503 0.03350000083446503 0.20043161310430982" />
   </geometry>
  </collision>
  <visual >
   <origin  rpy="0.0 0.0367288820213727 0.0"  xyz="0.0016375212975714426 0.0 0.04456397245533662" />
   <geometry >
    <box  size="0.03350000083446503 0.03350000083446503 0.05568809516494515" />
   </geometry>
   <material  name="L7_Material" >
    <color  rgba="0.5176470588235295 0.5843137254901961 0.8705882352941177 1.0" />
   </material>
  </visual>
  <collision  name="L7_1_Collision" >
   <origin  rpy="0.0 0.0367288820213727 0.0"  xyz="0.0016375212975714426 0.0 0.04456397245533662" />
   <geometry >
    <box  size="0.03350000083446503 0.03350000083446503 0.05568809516494515" />
   </geometry>
  </collision>
  <collision  name="L7_1_Collision" >
   <origin  rpy="0.0 0.0367288820213727 0.0"  xyz="0.0016375212975714426 0.0 0.04456397245533662" />
   <geometry >
    <box  size="0.03350000083446503 0.03350000083446503 0.05568809516494515" />
   </geometry>
  </collision>
  <visual >
   <origin  rpy="3.141592653589793 0.022613269098967104 3.141592653589793"  xyz="0.0016375212975714912 0.0 0.16152977942472405" />
   <geometry >
    <box  size="0.03350000083446503 0.03350000083446503 0.11134069948143371" />
   </geometry>
   <material  name="L7_Material" >
    <color  rgba="0.5176470588235295 0.5843137254901961 0.8705882352941177 1.0" />
   </material>
  </visual>
  <collision  name="L7_2_Collision" >
   <origin  rpy="3.141592653589793 0.022613269098967104 3.141592653589793"  xyz="0.0016375212975714912 0.0 0.16152977942472405" />
   <geometry >
    <box  size="0.03350000083446503 0.03350000083446503 0.11134069948143371" />
   </geometry>
  </collision>
  <collision  name="L7_2_Collision" >
   <origin  rpy="3.141592653589793 0.022613269098967104 3.141592653589793"  xyz="0.0016375212975714912 0.0 0.16152977942472405" />
   <geometry >
    <box  size="0.03350000083446503 0.03350000083446503 0.11134069948143371" />
   </geometry>
  </collision>
  <inertial >
   <origin  rpy="0.0 0.0 0.0"  xyz="0.00109 0.0 0.10769" />
   <mass  value="0.1994003888739811" />
   <inertia  ixy="-1.5959512447849774e-22"  ixz="0.0009152619907665016"  iyz="2.042817593324771e-20"  iyy="0.031451319530844166"  ixx="0.03140102996335566"  izz="8.75857504155284e-05" />
  </inertial>
 </link>
 <link  name="EE" >
  <visual >
   <origin  rpy="0.0 0.0 0.0"  xyz="0.0 0.0 0.0" />
   <geometry >
    <sphere  radius="0.002142857142857143" />
   </geometry>
   <material  name="EE_Material" >
    <color  rgba="0.6431372549019608 0.6666666666666666 0.9058823529411765 1.0" />
   </material>
  </visual>
  <collision  name="EE_Collision" >
   <origin  rpy="0.0 0.0 0.0"  xyz="0.0 0.0 0.0" />
   <geometry >
    <sphere  radius="0.002142857142857143" />
   </geometry>
  </collision>
  <inertial >
   <origin  rpy="0.0 0.0 0.0"  xyz="0.0 0.0 0.0" />
   <mass  value="2.982076683750377e-05" />
   <inertia  ixy="0.0"  ixz="0.0"  iyz="0.0"  iyy="5.477283704847632e-11"  ixx="5.477283704847632e-11"  izz="5.477283704847632e-11" />
  </inertial>
 </link>
 <link  name="L8" >
  <visual >
   <origin  rpy="0.0 0.0 0.0"  xyz="0.0 0.0 0.07968" />
   <geometry >
    <box  size="0.0335 0.0335 0.1258643623900902" />
   </geometry>
   <material  name="L8_Material" >
    <color  rgba="0.01568627450980392 0.5058823529411764 0.29411764705882354 1.0" />
   </material>
  </visual>
  <collision  name="L8_Collision" >
   <origin  rpy="0.0 0.0 0.0"  xyz="0.0 0.0 0.07968" />
   <geometry >
    <box  size="0.0335 0.0335 0.1258643623900902" />
   </geometry>
  </collision>
  <inertial >
   <origin  rpy="0.0 0.0 0.0"  xyz="0.0 0.0 0.07968" />
   <mass  value="0.10219812660647752" />
   <inertia  ixy="0.0"  ixz="0.0"  iyz="0.0"  iyy="0.00014447483204650387"  ixx="0.00014447483204650387"  izz="1.9115307930686567e-05" />
  </inertial>
 </link>
 <link  name="L5" >
  <visual >
   <origin  rpy="0.0 0.0 0.0"  xyz="-1.734723475976807e-17 0.0 0.09124157961149074" />
   <geometry >
    <box  size="0.03350000083446503 0.03350000083446503 0.14898315838851645" />
   </geometry>
   <material  name="L5_Material" >
    <color  rgba="0.0 0.6627450980392157 0.3607843137254902 1.0" />
   </material>
  </visual>
  <collision  name="L5_0_Collision" >
   <origin  rpy="0.0 0.0 0.0"  xyz="-1.734723475976807e-17 0.0 0.09124157961149074" />
   <geometry >
    <box  size="0.03350000083446503 0.03350000083446503 0.14898315838851645" />
   </geometry>
  </collision>
  <collision  name="L5_0_Collision" >
   <origin  rpy="0.0 0.0 0.0"  xyz="-1.734723475976807e-17 0.0 0.09124157961149074" />
   <geometry >
    <box  size="0.03350000083446503 0.03350000083446503 0.14898315838851645" />
   </geometry>
  </collision>
  <visual >
   <origin  rpy="0.0 -1.0455496452403543 0.0"  xyz="-0.05165361581932172 0.0 0.029935830918648574" />
   <geometry >
    <box  size="0.03350000083446503 0.03350000083446503 0.08590267920245875" />
   </geometry>
   <material  name="L5_Material" >
    <color  rgba="0.0 0.6627450980392157 0.3607843137254902 1.0" />
   </material>
  </visual>
  <collision  name="L5_1_Collision" >
   <origin  rpy="0.0 -1.0455496452403543 0.0"  xyz="-0.05165361581932172 0.0 0.029935830918648574" />
   <geometry >
    <box  size="0.03350000083446503 0.03350000083446503 0.08590267920245875" />
   </geometry>
  </collision>
  <collision  name="L5_1_Collision" >
   <origin  rpy="0.0 -1.0455496452403543 0.0"  xyz="-0.05165361581932172 0.0 0.029935830918648574" />
   <geometry >
    <box  size="0.03350000083446503 0.03350000083446503 0.08590267920245875" />
   </geometry>
  </collision>
  <visual >
   <origin  rpy="-3.141592653589793 -0.7001573854515128 3.141592653589793"  xyz="-0.051653615819321735 0.0 0.1211774105301393" />
   <geometry >
    <box  size="0.03350000083446503 0.03350000083446503 0.12683079283911472" />
   </geometry>
   <material  name="L5_Material" >
    <color  rgba="0.0 0.6627450980392157 0.3607843137254902 1.0" />
   </material>
  </visual>
  <collision  name="L5_2_Collision" >
   <origin  rpy="-3.141592653589793 -0.7001573854515128 3.141592653589793"  xyz="-0.051653615819321735 0.0 0.1211774105301393" />
   <geometry >
    <box  size="0.03350000083446503 0.03350000083446503 0.12683079283911472" />
   </geometry>
  </collision>
  <collision  name="L5_2_Collision" >
   <origin  rpy="-3.141592653589793 -0.7001573854515128 3.141592653589793"  xyz="-0.051653615819321735 0.0 0.1211774105301393" />
   <geometry >
    <box  size="0.03350000083446503 0.03350000083446503 0.12683079283911472" />
   </geometry>
  </collision>
  <inertial >
   <origin  rpy="0.0 0.0 0.0"  xyz="-0.03444 0.0 0.08078" />
   <mass  value="0.3367732022657562" />
   <inertia  ixy="-1.2611334412390474e-20"  ixz="-0.0002891512305023703"  iyz="4.125470129719375e-21"  iyy="0.009257484637084243"  ixx="0.008725859972212488"  izz="0.0005946152890503301" />
  </inertial>
 </link>
 <link  name="L4" >
  <visual >
   <origin  rpy="0.0 0.0 0.0"  xyz="0.0 0.0 0.09379" />
   <geometry >
    <box  size="0.0335 0.0335 0.15407310678239564" />
   </geometry>
   <material  name="L4_Material" >
    <color  rgba="0.0 0.8274509803921568 0.4196078431372549 1.0" />
   </material>
  </visual>
  <collision  name="L4_Collision" >
   <origin  rpy="0.0 0.0 0.0"  xyz="0.0 0.0 0.09379" />
   <geometry >
    <box  size="0.0335 0.0335 0.15407310678239564" />
   </geometry>
  </collision>
  <inertial >
   <origin  rpy="0.0 0.0 0.0"  xyz="0.0 0.0 0.09379" />
   <mass  value="0.12510278981749598" />
   <inertia  ixy="0.0"  ixz="0.0"  iyz="0.0"  iyy="0.00025917933028651126"  ixx="0.00025917933028651126"  izz="2.339943431211415e-05" />
  </inertial>
 </link>
 <link  name="L3" >
  <visual >
   <origin  rpy="0.0 0.0 0.0"  xyz="0.0 0.0 0.05281" />
   <geometry >
    <box  size="0.0335 0.0335 0.07212196741208717" />
   </geometry>
   <material  name="L3_Material" >
    <color  rgba="0.0 1.0 0.4666666666666667 1.0" />
   </material>
  </visual>
  <collision  name="L3_Collision" >
   <origin  rpy="0.0 0.0 0.0"  xyz="0.0 0.0 0.05281" />
   <geometry >
    <box  size="0.0335 0.0335 0.07212196741208717" />
   </geometry>
  </collision>
  <inertial >
   <origin  rpy="0.0 0.0 0.0"  xyz="0.0 0.0 0.05281" />
   <mass  value="0.058560896958621995" />
   <inertia  ixy="0.0"  ixz="0.0"  iyz="0.0"  iyy="3.0860754219295084e-05"  ixx="3.0860754219295084e-05"  izz="1.095332776863559e-05" />
  </inertial>
 </link>
 <joint  type="revolute"  name="Main_ground" >
  <parent  link="G" />
  <child  link="L6" />
  <origin  rpy="3.141592653589793 0.17670885607003695 3.141592653589793"  xyz="0.0 0.0 0.0" />
  <axis  xyz="0 1 0" />
  <limit  effort="10.2"  lower="-3.141592653589793"  upper="3.141592653589793"  velocity="23.99988291783386" />
  <dynamics  friction="0"  damping="0.05" />
 </joint>
 <joint  type="fixed"  name="Main_ground_G_WeldActuator" >
  <parent  link="G" />
  <child  link="Main_ground_GActuator" />
  <origin  rpy="-1.5707963267948966 0.17670885607003695 -3.141592653589793"  xyz="0.0 0.03675000041723252 0.0" />
 </joint>
 <link  name="Main_ground_GActuator" >
  <visual >
   <geometry >
    <cylinder  radius="0.048"  length="0.04" />
   </geometry>
   <material  name="Main_ground_GActuator_Material" >
    <color  rgba="0.1568627450980392 0.42745098039215684 0.8 0.9" />
   </material>
  </visual>
  <inertial >
   <inertia  ixy="0.0"  ixz="0.0"  iyz="0.0"  iyy="0.0067466666666666664"  ixx="0.0067466666666666664"  izz="0.01056" />
   <mass  value="0.44" />
  </inertial>
 </link>
 <link  name="Main_ground_GUnit" >
  <visual >
   <geometry >
    <cylinder  radius="0.016750000417232513"  length="0.03350000083446503" />
   </geometry>
   <material  name="Main_ground_GUnit_Material" >
    <color  rgba="0.1568627450980392 0.42745098039215684 0.8 0.9" />
   </material>
  </visual>
  <inertial >
   <inertia  ixy="0.0"  ixz="0.0"  iyz="0.0"  iyy="0.0006979166840513548"  ixx="0.0006979166840513548"  izz="0.0008375000208616257" />
   <mass  value="0.1" />
  </inertial>
 </link>
 <joint  type="fixed"  name="Main_ground_G_WeldUnit" >
  <parent  link="G" />
  <child  link="Main_ground_GUnit" />
  <origin  rpy="-1.5707963267948966 0.17670885607003695 -3.141592653589793"  xyz="0.0 0.0 0.0" />
 </joint>
 <joint  type="revolute"  name="Main_knee" >
  <parent  link="L6" />
  <child  link="L7" />
  <origin  rpy="0.0 0.3053056067249402 0.0"  xyz="4.5102810375396984e-17 0.0 0.1706575518399347" />
  <axis  xyz="0 1 0" />
  <limit  effort="600.0"  lower="-3.141592653589793"  upper="3.141592653589793"  velocity="6.283185307179586" />
  <dynamics  friction="0"  damping="0.05" />
 </joint>
 <link  name="Main_knee_L6Unit" >
  <visual >
   <geometry >
    <cylinder  radius="0.016"  length="0.03" />
   </geometry>
   <material  name="Main_knee_L6Unit_Material" >
    <color  rgba="0.37254901960784315 0.5019607843137255 0.8352941176470589 0.9" />
   </material>
  </visual>
  <inertial >
   <inertia  ixy="0.0"  ixz="0.0"  iyz="0.0"  iyy="0.00065"  ixx="0.00065"  izz="0.0008" />
   <mass  value="0.1" />
  </inertial>
 </link>
 <joint  type="fixed"  name="Main_knee_L6_WeldUnit" >
  <parent  link="L6" />
  <child  link="Main_knee_L6Unit" />
  <origin  rpy="1.5707963267948966 0.30530560672494 0.0"  xyz="4.5102810375396984e-17 0.0 0.1706575518399347" />
 </joint>
 <joint  type="fixed"  name="Main_ee" >
  <parent  link="L7" />
  <child  link="EE" />
  <origin  rpy="3.141592653589793 0.12859675065490328 3.141592653589793"  xyz="9.71445146547012e-17 0.0 0.23393161393877485" />
 </joint>
 <link  name="Main_ee_L7Unit" >
  <visual >
   <geometry >
    <cylinder  radius="0.016"  length="0.03" />
   </geometry>
   <material  name="Main_ee_L7Unit_Material" >
    <color  rgba="0.5176470588235295 0.5843137254901961 0.8705882352941177 0.9" />
   </material>
  </visual>
  <inertial >
   <inertia  ixy="0.0"  ixz="0.0"  iyz="0.0"  iyy="0.00065"  ixx="0.00065"  izz="0.0008" />
   <mass  value="0.1" />
  </inertial>
 </link>
 <joint  type="fixed"  name="Main_ee_L7_WeldUnit" >
  <parent  link="L7" />
  <child  link="Main_ee_L7Unit" />
  <origin  rpy="-1.5707963267948966 0.1285967506549035 -3.141592653589793"  xyz="9.71445146547012e-17 0.0 0.23393161393877485" />
 </joint>
 <link  name="Main_connection_2_L7Pseudo" >
  <visual >
   <geometry >
    <sphere  radius="0.02392857202461788" />
   </geometry>
   <material  name="Main_connection_2_L7Pseudo_Material" >
    <color  rgba="0.5176470588235295 0.5843137254901961 0.8705882352941177 0.5" />
   </material>
  </visual>
  <inertial >
   <mass  value="0.05" />
   <inertia  ixy="0.0"  ixz="0.0"  iyz="0.0"  iyy="1.145153118274651e-05"  ixx="1.145153118274651e-05"  izz="1.145153118274651e-05" />
  </inertial>
 </link>
 <joint  type="revolute"  name="Main_connection_2_L7_revolute" >
  <parent  link="L7" />
  <child  link="Main_connection_2_L7Pseudo" />
  <origin  rpy="3.141592653589793 0.12859675065490328 3.141592653589793"  xyz="0.003275042595142885 0.0 0.08912794491067325" />
  <axis  xyz="0 1 0" />
  <limit  effort="600.0"  lower="-3.141592653589793"  upper="3.141592653589793"  velocity="6.283185307179586" />
  <dynamics  friction="0"  damping="0.05" />
 </joint>
 <joint  type="fixed"  name="Main_connection_2_L7_Weld" >
  <parent  link="L8" />
  <child  link="Main_connection_2_L8Pseudo" />
  <origin  rpy="3.141592653589793 -0.8431117770064139 3.141592653589793"  xyz="2.7755575615628914e-17 0.0 0.1593643623900902" />
 </joint>
 <link  name="Main_connection_2_L8Pseudo" >
  <visual >
   <geometry >
    <sphere  radius="0.02392857142857143" />
   </geometry>
   <material  name="Main_connection_2_L8Pseudo_Material" >
    <color  rgba="0.01568627450980392 0.5058823529411764 0.29411764705882354 0.5" />
   </material>
  </visual>
  <inertial >
   <mass  value="0.05" />
   <inertia  ixy="0.0"  ixz="0.0"  iyz="0.0"  iyy="1.1451530612244902e-05"  ixx="1.1451530612244902e-05"  izz="1.1451530612244902e-05" />
  </inertial>
 </link>
 <joint  type="revolute"  name="branch_0" >
  <parent  link="L5" />
  <child  link="L8" />
  <origin  rpy="0.0 -1.2518603806985196 0.0"  xyz="-3.469446951953614e-17 0.0 0.18248315922298147" />
  <axis  xyz="0 1 0" />
  <limit  effort="600.0"  lower="-3.141592653589793"  upper="3.141592653589793"  velocity="6.283185307179586" />
  <dynamics  friction="0"  damping="0.05" />
 </joint>
 <link  name="branch_0_L5Unit" >
  <visual >
   <geometry >
    <cylinder  radius="0.016"  length="0.03" />
   </geometry>
   <material  name="branch_0_L5Unit_Material" >
    <color  rgba="0.0 0.6627450980392157 0.3607843137254902 0.9" />
   </material>
  </visual>
  <inertial >
   <inertia  ixy="0.0"  ixz="0.0"  iyz="0.0"  iyy="0.00065"  ixx="0.00065"  izz="0.0008" />
   <mass  value="0.1" />
  </inertial>
 </link>
 <joint  type="fixed"  name="branch_0_L5_WeldUnit" >
  <parent  link="L5" />
  <child  link="branch_0_L5Unit" />
  <origin  rpy="1.5707963267948957 -1.2518603806985196 5.551115123125783e-16"  xyz="-3.469446951953614e-17 0.0 0.18248315922298147" />
 </joint>
 <link  name="Main_connection_1_L6Pseudo" >
  <visual >
   <geometry >
    <sphere  radius="0.02392857202461788" />
   </geometry>
   <material  name="Main_connection_1_L6Pseudo_Material" >
    <color  rgba="0.37254901960784315 0.5019607843137255 0.8352941176470589 0.5" />
   </material>
  </visual>
  <inertial >
   <mass  value="0.05" />
   <inertia  ixy="0.0"  ixz="0.0"  iyz="0.0"  iyy="1.145153118274651e-05"  ixx="1.145153118274651e-05"  izz="1.145153118274651e-05" />
  </inertial>
 </link>
 <joint  type="revolute"  name="Main_connection_1_L6_revolute" >
  <parent  link="L6" />
  <child  link="Main_connection_1_L6Pseudo" />
  <origin  rpy="0.0 0.3053056067249402 0.0"  xyz="-0.025427975224150245 0.0 0.08430483060892775" />
  <axis  xyz="0 1 0" />
  <limit  effort="600.0"  lower="-3.141592653589793"  upper="3.141592653589793"  velocity="6.283185307179586" />
  <dynamics  friction="0"  damping="0.05" />
 </joint>
 <joint  type="fixed"  name="Main_connection_1_L6_Weld" >
  <parent  link="L5" />
  <child  link="Main_connection_1_L5Pseudo" />
  <origin  rpy="0.0 -0.28015185303720225 0.0"  xyz="-0.10330723163864344 0.0 0.05987166183729714" />
 </joint>
 <link  name="Main_connection_1_L5Pseudo" >
  <visual >
   <geometry >
    <sphere  radius="0.02392857202461788" />
   </geometry>
   <material  name="Main_connection_1_L5Pseudo_Material" >
    <color  rgba="0.0 0.6627450980392157 0.3607843137254902 0.5" />
   </material>
  </visual>
  <inertial >
   <mass  value="0.05" />
   <inertia  ixy="0.0"  ixz="0.0"  iyz="0.0"  iyy="1.145153118274651e-05"  ixx="1.145153118274651e-05"  izz="1.145153118274651e-05" />
  </inertial>
 </link>
 <joint  type="revolute"  name="branch_1" >
  <parent  link="L4" />
  <child  link="L5" />
  <origin  rpy="3.141592653589793 0.5256308447594713 3.141592653589793"  xyz="1.3877787807814457e-17 0.0 0.18757310678239564" />
  <axis  xyz="0 1 0" />
  <limit  effort="600.0"  lower="-3.141592653589793"  upper="3.141592653589793"  velocity="6.283185307179586" />
  <dynamics  friction="0"  damping="0.05" />
 </joint>
 <link  name="branch_1_L4Unit" >
  <visual >
   <geometry >
    <cylinder  radius="0.016"  length="0.03" />
   </geometry>
   <material  name="branch_1_L4Unit_Material" >
    <color  rgba="0.0 0.8274509803921568 0.4196078431372549 0.9" />
   </material>
  </visual>
  <inertial >
   <inertia  ixy="0.0"  ixz="0.0"  iyz="0.0"  iyy="0.00065"  ixx="0.00065"  izz="0.0008" />
   <mass  value="0.1" />
  </inertial>
 </link>
 <joint  type="fixed"  name="branch_1_L4_WeldUnit" >
  <parent  link="L4" />
  <child  link="branch_1_L4Unit" />
  <origin  rpy="-1.5707963267948966 0.5256308447594713 -3.141592653589793"  xyz="1.3877787807814457e-17 0.0 0.18757310678239564" />
 </joint>
 <joint  type="revolute"  name="Ground_connection" >
  <parent  link="G" />
  <child  link="L3" />
  <origin  rpy="3.141592653589793 -0.3277385067805554 3.141592653589793"  xyz="-0.148 0.0 0.006" />
  <axis  xyz="0 1 0" />
  <limit  effort="10.2"  lower="-3.141592653589793"  upper="3.141592653589793"  velocity="23.99988291783386" />
  <dynamics  friction="0"  damping="0.05" />
 </joint>
 <joint  type="fixed"  name="Ground_connection_G_WeldActuator" >
  <parent  link="G" />
  <child  link="Ground_connection_GActuator" />
  <origin  rpy="-1.5707963267948966 -0.3277385067805554 -3.141592653589793"  xyz="-0.148 0.036750000000000005 0.006" />
 </joint>
 <link  name="Ground_connection_GActuator" >
  <visual >
   <geometry >
    <cylinder  radius="0.048"  length="0.04" />
   </geometry>
   <material  name="Ground_connection_GActuator_Material" >
    <color  rgba="0.1568627450980392 0.42745098039215684 0.8 0.9" />
   </material>
  </visual>
  <inertial >
   <inertia  ixy="0.0"  ixz="0.0"  iyz="0.0"  iyy="0.0067466666666666664"  ixx="0.0067466666666666664"  izz="0.01056" />
   <mass  value="0.44" />
  </inertial>
 </link>
 <link  name="Ground_connection_GUnit" >
  <visual >
   <geometry >
    <cylinder  radius="0.01675"  length="0.0335" />
   </geometry>
   <material  name="Ground_connection_GUnit_Material" >
    <color  rgba="0.1568627450980392 0.42745098039215684 0.8 0.9" />
   </material>
  </visual>
  <inertial >
   <inertia  ixy="0.0"  ixz="0.0"  iyz="0.0"  iyy="0.0006979166666666668"  ixx="0.0006979166666666668"  izz="0.0008375000000000001" />
   <mass  value="0.1" />
  </inertial>
 </link>
 <joint  type="fixed"  name="Ground_connection_G_WeldUnit" >
  <parent  link="G" />
  <child  link="Ground_connection_GUnit" />
  <origin  rpy="-1.5707963267948966 -0.3277385067805554 -3.141592653589793"  xyz="-0.148 0.0 0.006" />
 </joint>
 <joint  type="revolute"  name="branch_2" >
  <parent  link="L3" />
  <child  link="L4" />
  <origin  rpy="3.141592653589793 -0.6066409416710212 3.141592653589793"  xyz="0.0 0.0 0.10562196741208714" />
  <axis  xyz="0 1 0" />
  <limit  effort="600.0"  lower="-3.141592653589793"  upper="3.141592653589793"  velocity="6.283185307179586" />
  <dynamics  friction="0"  damping="0.05" />
 </joint>
 <link  name="branch_2_L3Unit" >
  <visual >
   <geometry >
    <cylinder  radius="0.016"  length="0.03" />
   </geometry>
   <material  name="branch_2_L3Unit_Material" >
    <color  rgba="0.0 1.0 0.4666666666666667 0.9" />
   </material>
  </visual>
  <inertial >
   <inertia  ixy="0.0"  ixz="0.0"  iyz="0.0"  iyy="0.00065"  ixx="0.00065"  izz="0.0008" />
   <mass  value="0.1" />
  </inertial>
 </link>
 <joint  type="fixed"  name="branch_2_L3_WeldUnit" >
  <parent  link="L3" />
  <child  link="branch_2_L3Unit" />
  <origin  rpy="-1.5707963267948966 -0.6066409416710211 -3.141592653589793"  xyz="0.0 0.0 0.10562196741208714" />
 </joint>
</robot>
